EventId,EventTemplate,Occurrences
f15c1cae,Content,1
e17b68d6,Workload started!,876
96691030,Create image <*>,876
f7725eaf,openstack image create --public --disk-format qcow2 --container-format bare --file cirros-0.4.0-x86_64-disk.img <*>,1752
9125862b,GET <*> v3,41537
482c7d15,POST <*> v3 auth tokens,87102
b2c92d46,Using the in-process token cache is deprecated as of the 4.2.0 release and may be removed in the 5.0.0 release or the 'O' development cycle. The in-process cache causes inconsistent results and high memory usage. When the feature is removed the auth_token middleware will not cache tokens by default which may result in performance issues. It is recommended to use memcache for the auth_token token cache by setting the memcached_servers option.,8434
bfcb41c6,GET 10.0.20.24:35357,2143
8aa0fa07,POST <*> v2.0 tokens,8180
3dc1e63c,GET <*> v3 <*> <*>,121473
e46a9e11,"""""""GET v2 <*> <*> HTTP 1.1"""" <*> <*> <*>",26154
b8be6124,"""""""POST v2 images HTTP 1.1"""" 201 867 <*>",876
32433681,"""""""PUT v2 images <*> file HTTP 1.1"""" 204 213 <*>",876
a2773886,<*> image is not in ACTIVE state (status 1)!...retry (#0) wait: 0 sec,876
9a0fd529,"""""""GET v2 <*> HTTP 1.1"""" <*> <*> <*>",4684
9abf2249,<*> image is ACTIVE...great!,876
5faa897d,Create keypair <*>,876
97b4a7ff,openstack keypair create --public-key tmp <*> <*>,1746
1e7c6fb2,"""10.0.20.24 """"GET <*> <*> <*> <*> status: 200 len: <*> <*> <*>",139
25df7a74,Final resource view: name=localhost.localdomain phys_ram=16383MB <*> phys_disk=143GB <*> total_vcpus=8 <*> pci_stats=,7680
8779390e,"""Option """"driver"""" from group """"token"""" is deprecated for removal. Its value may be silently ignored in the future.""",8139
2e820dd1,"<*> """"POST <*> <*> <*> HTTP 1.1"""" status: <*> len: <*> time: <*>",7522
133ead9c,<*> key-pair is not still created (status 1)!...retry (#0) wait: 0 sec,1746
ab25b280,Total expired tokens removed: 0,7925
4a47a7d6,Unique keys not in sort_keys. The sorting order may be unstable.,1746
0340ec46,"<*> """"GET <*> <*> <*> HTTP 1.1"""" status: <*> len: <*> time: <*>",53822
9a01a906,<*> key-pair was created successfully...great!,873
e58944a5,Create security group with SSH enabled,873
fae841a5,openstack security group <*> <*>,3094
7f748d7c,"<*> """"GET <*> <*> status: 200 len: <*> <*> <*>",18069
a25baed4,Loaded quota_driver: <neutron.db.quota.driver.DbQuotaDriver object at <*>,2702
a8538376,Security group rule updated,8133
c926a331,"<*> """"POST v2.0 <*> HTTP 1.1"""" status: 201 len: <*> time: <*>",5901
e939f1ee,openstack security group rule create --proto tcp --dst-port 22 <*>,1746
72812c01,show failed (client error): The resource could not be found.,7459
14267f72,<*> security group was created successfully...great!,873
5ee93470,openstack network set --external public,1746
5aa9b8bc,GET failed (client error): The resource could not be found.,6432
5258d759,openstack network <*> <*>,3094
40dc96e4,Added segment <*> of type vxlan for network <*>,873
e6eb2710,<*> private network is not in ACTIVE state (status <*> <*> wait: <*> sec,874
8f3fa71e,Successfully synced instances from host 'localhost.localdomain'.,3811
0b99a07f,<*> network is ACTIVE...great!,873
6c8fcfb3,Create subnet <*> on network <*> with range <*> 24'...,873
a15c1395,openstack subnet create --subnet-range <*> 24 --network <*> --dns-nameserver 8.8.4.4 <*>,1746
a9bb7399,<*> private subnet is still not created (status 1)!...retry (#0) wait: 0 sec,873
cbb184dd,},7917
3777cf52,Assigning <*> as local vlan for <*>,985
9371d7a2,),8949
756e8658,Skipping ARP spoofing rules for port <*> because it has port security disabled,5285
34d55132,", tenant_id = <*> updated_at = <*>",6794
c2702041,completed.,11460
94cdcc95,Refresh firewall rules,3975
fe21cd54,"<*> """"GET <*> <*> <*> <*> HTTP 1.1"""" status: <*> len: <*> time: <*>",36734
ed2d6c7d,<*> private subnet is created...great!,873
98ac476e,Create router <*> for instance <*>,873
5dc0e1b6,openstack router <*> <*>,3094
ec9e91c6,<*> router is not in ACTIVE state (status unknown)!...retry (#0) wait: 0 sec,873
2ae44b83,<*> router is ACTIVE...great!,873
23338614,<*> router has still no interfaces on <*> (status 1)!...retry (#0) wait: 0 sec,873
8df33b2f,openstack router <*> <*> tempest-router-1529976062 <*>,4
2e051749,"<*> """"PUT v2.0 routers <*> <*> HTTP 1.1"""" status: 200 len: 508 time: <*>",1547
ec0dc25f,was added to <*>,873
0b41af55,neutron router-gateway-set <*> public,1746
8eb6c337,"""Option """"admin_bind_host"""" from group """"eventlet_server"""" is deprecated for removal (Support for running keystone under eventlet has been removed in the Newton release. These options remain for backwards compatibility because they are used for URL substitutions.). Its value may be silently ignored in the future.""",173
60f527e7,"""Option """"admin_port"""" from group """"eventlet_server"""" is deprecated for removal (Support for running keystone under eventlet has been removed in the Newton release. These options remain for backwards compatibility because they are used for URL substitutions.). Its value may be silently ignored in the future.""",166
f8672e1d,"""Option """"public_bind_host"""" from group """"DEFAULT"""" is deprecated. Use option """"public_bind_host"""" from group """"eventlet_server"""".""",79
8012b97b,"""Option """"public_bind_host"""" from group """"eventlet_server"""" is deprecated for removal (Support for running keystone under eventlet has been removed in the Newton release. These options remain for backwards compatibility because they are used for URL substitutions.). Its value may be silently ignored in the future.""",163
313300ec,"""Option """"public_port"""" from group """"eventlet_server"""" is deprecated for removal (Support for running keystone under eventlet has been removed in the Newton release. These options remain for backwards compatibility because they are used for URL substitutions.). Its value may be silently ignored in the future.""",209
1eab9f82,"""Option """"dhcp_domain"""" from group """"DEFAULT"""" is deprecated for removal (""",3417
143a1952,"""Option """"firewall_driver"""" from group """"DEFAULT"""" is deprecated for removal (""",258
af27d0d6,"""Option """"force_snat_range"""" from group """"DEFAULT"""" is deprecated for removal (""",258
b1d8fcbc,"""Option """"use_baremetal_filters"""" from group """"filter_scheduler"""" is deprecated for removal (""",258
264ba4b2,"""Option """"live_migration_uri"""" from group """"libvirt"""" is deprecated for removal (""",259
5cf6b45f,AuthToken middleware is set with keystone_authtoken.service_token_roles_required set to False. This is backwards compatible but deprecated behaviour. Please set this to True.,259
3b4c7c73,"""Option """"public_port"""" from group """"DEFAULT"""" is deprecated. Use option """"public_port"""" from group """"eventlet_server"""".""",76
15081a26,"""Option """"admin_bind_host"""" from group """"DEFAULT"""" is deprecated. Use option """"admin_bind_host"""" from group """"eventlet_server"""".""",72
19bc5f9c,"""Option """"admin_port"""" from group """"DEFAULT"""" is deprecated. Use option """"admin_port"""" from group """"eventlet_server"""".""",71
904acae4,Deprecated: authenticate of the v2 Authentication APIs is deprecated as of Mitaka in favor of a similar function in the v3 Authentication APIs and may be removed in T.,612
8fbcaef2,"<*> """"PUT v2.0 <*> <*> HTTP 1.1"""" status: 200 len: <*> time: <*>",2971
27410910,neutron CLI is deprecated and will be removed in the future. Use openstack CLI instead.,873
10b56710,Create instance <*> and boot it.,873
6adf97f8,None,873
2babe530,Details:,873
ca263171,........image name = <*>,873
7182e0a5,........network = <*>,873
b4af6ff7,........security group = <*>,873
1646b311,........key name = <*>,873
4e2497e3,openstack server create --flavor m1.tiny --image <*> --nic <*> --security-group <*> --key-name <*> <*>,1592
158bc811,HTTP exception thrown: Impossibile trovare la tipologia m1.tiny.,796
1152f528,api_servers with fully qualified url including scheme (http https),18538
2e63aaa5,"A valid token was submitted as a service token, but it was not a valid service token. This is incorrect but backwards compatible behaviour. This will be removed in future releases.",2722
43838316,"<*> """"GET v2.0 <*> = <*> = <*> HTTP 1.1"""" status: 200 len: <*> time: <*>",9577
555fe965,<*> instance is not in ACTIVE state (status <*> <*> wait: <*> sec,1513
b992222b,Updating bandwidth usage cache,421
67e96752,Bandwidth usage not supported by hypervisor.,418
3cf912e7,"<*> """"GET <*> <*> HTTP 1.1"""" status: <*> len: <*> time: <*>",109405
d0395c88,"""10.0.20.24 """"GET <*> <*> <*> status: 200 len: <*> <*> <*>",779
71203b51,<*> instance is not in ACTIVE state (status <*>,1923
30f03bda,"<*> """"PUT placement allocations <*> status: 204 len: 0 microversion: 1.10""",791
7b91c81f,"Attempting claim on node localhost.localdomain: memory 512 MB, disk 1 GB, vcpus 1 CPU",716
04fbd2dc,"Total di memoria: 16383 MB, used: <*> MB",607
3076431a,"di memoria limit: 24574.50 MB, free: <*> MB",617
4d90d03a,"disco limit: 143.00 GB, free: <*> GB",586
b51d1b4e,"Total vcpu: 8 VCPU, used: <*> VCPU",581
08d43131,"vcpu limit: 128.00 VCPU, free: <*> VCPU",745
fd65a5f7,Claim successful on node localhost.localdomain,745
7d8b6b51,"While synchronizing instance power states, found <*> instances in the database and <*> instances on the hypervisor.",153
2368ba13,Creating image,730
943309cb,"""""""GET v2 images <*> file HTTP 1.1"""" 200 12716291 <*>",1515
57ee55c5,Running privsep helper:,717
8addabe3,Creating event <*> for instance <*> on localhost.localdomain,5345
bfe3c2dc,"Nova event response: <*>u'status': u'completed', u'tag': <*> u'name': <*> u'server_uuid': <*> u'code': 200}",5342
365b0598,privsep daemon starting,717
5a40cee7,privsep process running with uid gid: 0 0,717
62c77ac0,privsep daemon running as pid <*>,717
93302cb2,Spawned new privsep daemon via rootwrap,717
c6997dc1,Successfully plugged vif <*>,1373
7e4c0cc9,VM Avviato (Lifecycle Event),1351
06e3c7db,VM In pausa (Lifecycle Event),699
158153e3,During sync_power_state the instance has a pending task <*> Skip.,1895
dc06b2db,VM Ripristinato (Lifecycle Event),2042
70439dff,Instance spawned successfully.,696
41a2da91,Took <*> seconds to <*> the instance on the hypervisor.,1390
7824976e,Took <*> seconds to build instance.,691
a0c9927d,tempest-INSTANCE_SAMPLE-1529976062 instance <*> <*>,4
e5675f94,Create floating ip for instance <*>,796
1413eba9,openstack floating ip create --project <*> public,1592
d80e04f7,"<*> """"GET 2009-04-04 meta-data public-keys 0 openssh-key HTTP 1.1"""" status: <*> len: <*> time: <*>",2646
672be73a,Could not find <*> <*> <*> Could not find <*> <*>,3492
bad50744,GET <*> v3 <*>,3492
b5e7cf04,Created floating IP <*>,796
fb23c5d8,Add floating IP <*> to instance <*>,796
5ac2bf2d,openstack ip floating add <*> <*>,1592
7260975b,HTTP exception thrown: Impossibile trovare l'istanza <*>,2146
17fc48e3,Device <*> already exists,685
e4c554dc,"<*> """"POST <*> <*> <*> <*> <*> HTTP 1.1"""" status: <*> len: <*> time: <*>",4204
49f1dd70,"""This command has been deprecated. Please use """"server add floating ip"""" instead.""",796
46e8c00e,Added floating IP <*> to instance <*>,796
4d312142,List all instances on tenants...,796
705643b1,nova list,1570
763d5c90,Create volume <*>,785
06380f71,openstack volume create --image <*> --size 1 --availability-zone nova <*>,1570
738ee853,POST <*> v2 <*> volumes,439
c36d9a6f,Create volume <*> <*> <*>,878
318a2988,Availability Zones retrieved successfully.,439
4ec40aaf,Deprecated: Quota predefinita per la risorsa: <*> Ã¨ impostato dall'indicatore quota predefinita: <*> Ã¨ ora obsoleta. Utilizzare la classe di quota predefinita per la quota predefinita.,1028
03dbcda1,<*> v2 <*> volumes returned with HTTP 202,439
b5926e2f,<*> volume status is not 'available' (status <*> <*> wait: <*> sec,3029
6f836261,", u'container_format': u'bare', u'created_at': datetime.datetime(2018, <*> <*> <*> <*> <*> tzinfo=<iso8601.Utc>), u'disk_format': u'qcow2', u'updated_at': datetime.datetime(2018, <*> <*> <*> <*> <*> tzinfo=<iso8601.Utc>), u'visibility': u'public', 'properties': <*>}, u'owner': <*> u'protected': False, u'id': <*> u'file': u' v2 images <*> file', u'checksum': u'443b7623e27ecf03dc9e01ee93f67afe', u'min_disk': 0, u'virtual_size': None, u'min_ram': 0, u'size': 12716032}}",426
b8f9fa4e,Image download 12.00 MB at <*> MB s,439
1a6940e4,GET 10.0.20.24:8776 <*> <*> volumes <*>,701
9e5acb06,Get all volumes completed successfully.,3407
a30a4752,<*> <*> <*> volumes <*> returned with HTTP <*>,5894
f7db18f2,Converted 44.00 MB image at <*> MB s,439
d3f509ca,Volume <*> <*> created successfully,439
e2807f5c,Created volume successfully.,439
3225db79,<*> volume status is <*>,1444
3802bfa6,Show volume list...,1461
24775af4,openstack volume list,2922
a690e058,Attach volume <*> to <*>,785
f4afa18c,openstack server add volume <*> <*> --device dev vdb,1352
4e83d0d5,Ignoring supplied device name: dev vdb,676
0b802ad2,"The support for the Cinder API v2 is deprecated, please upgrade to Cinder API v3.",5288
316ed4a1,Volume info retrieved successfully.,4141
7f725b07,POST <*> v2 <*> volumes <*> action,2069
adec6d2e,Reserve volume completed successfully.,415
0e88f807,<*> v2 <*> volumes <*> action returned with HTTP <*>,2069
0fdaaed4,Assertion results: <*>,872
f680c053,Failure!!!,198
0391cce4,Check SSH connection for instance <*> <*> reboot),1350
55527c61,SSH connection for instance <*> result => <*>,3981
038e2e65,Reboot instance <*>,676
b357cd9d,openstack server reboot --hard <*>,1348
0890241f,Rebooting instance,674
479432d5,Instance destroyed successfully.,1372
116e2d3d,Successfully unplugged vif <*>,1409
89727491,) removed,3470
ce52fea1,Instance rebooted successfully.,651
900df09f,Received unexpected event <*> for instance,1889
7dd5b09a,Start resources cleanup,674
130401c3,openstack ip floating delete <*>,1348
4e520e56,"<*> """"DELETE v2.0 <*> <*> HTTP 1.1"""" status: 204 len: 173 time: <*>",4094
bc0e4934,"""This command has been deprecated. Please use """"floating ip delete"""" instead.""",674
1d97a347,Port <*> not present in bridge br-int,1488
5c6a69b1,Remove device filter for,2612
393df78b,port_unbound(): net_uuid None not managed by VLAN manager,2618
ce020eaa,Removed floating ip <*>,674
e0e97934,nova list --all-tenant,1346
c895ebf6,"<*> """"DELETE <*> <*> <*> <*> HTTP 1.1"""" status: <*> len: <*> time: <*>",1761
ce0cacf4,Terminating instance,699
d3a31b11,Cleaned tempest created <*> <*>,2022
cd5c5a9d,openstack image list,1348
ad13cf03,Deleting instance files var lib nova instances <*>,695
2b100fa5,Deletion of var lib nova instances <*> complete,722
36893f37,Took <*> seconds to deallocate network for instance.,718
f640218d,Terminate volume connection completed successfully.,826
12e244f2,Unreserve volume completed successfully.,1
756f5c03,"Volume detach called, but volume not attached.",1
db8b66f4,Detach volume completed successfully.,825
e111acd7,Took <*> seconds to detach <*> volumes for instance.,638
77ecefbc,"<*> """"DELETE placement allocations <*> status: <*> len: <*> microversion: 1.0""",740
597630e5,Deleted allocation for instance <*>,731
43f4b51d,"""""""DELETE v2 images <*> HTTP 1.1"""" 204 213 <*>",674
76360587,cinder list --all-tenant,1348
68c0c87c,VM Di arresto (Lifecycle Event),671
772da746,DELETE <*> v3 <*> volumes <*>,415
eb724a68,Delete volume <*> <*> <*>,828
80d16f7b,Clean tempest created routers and networks...,674
2269fe8d,openstack router unset --external-gateway <*>,1348
3b166ddc,Skipping remove_export. No iscsi_target is presently exported for volume: <*>,413
83c0c88e,Successfully deleted volume: <*>,413
cc7873a9,Deleted volume successfully.,413
2570d89e,openstack port list <*> <*> --format=value -c ID,2696
c3f3f7c3,Removed port <*> on router <*>,674
177752f4,Removed router <*>,674
f072bdd2,openstack port delete <*>,1384
d1b73e49,Removed port <*>,692
cb2a6046,Reclaiming vlan = <*> from net-id = <*>,786
dd41f500,Synchronizing state,850
e1b327f0,All active networks have been fetched through RPC.,849
8c9bc2e3,Starting network <*> dhcp configuration,900
76f11b3f,Finished network <*> dhcp configuration,812
068b89c2,Synchronizing state complete,850
07875cdc,Removed network <*>,674
1278f398,Removed security group <*>,674
6bad77c0,openstack keypair delete <*>,1348
f83cb39a,Removed keypair <*>,674
28dd7d1f,openstack user delete <*>,1348
b32372ee,DELETE <*> v3 <*> <*>,2022
bf5b166b,Removed user <*>,674
427b131c,openstack project delete <*>,1348
3d94c8f8,Removed project <*>,674
976f424e,openstack domain set --disable <*>,1348
b740c466,PATCH <*> v3 domains <*>,674
32c0c23a,Disabled domain <*>,674
6d00d604,openstack domain delete <*>,1348
7b174bb9,Removed domain <*>,674
3c37ed53,End resources cleanup,674
dd21fd0b,openstack router <*> <*> tempest-router-1529986094 <*>,4
6520f3cf,"Total disco: 143 GB, used: <*> GB",591
41675ff6,privsep process running with capabilities (eff prm inh): <*> <*> none,353
5df6b32b,tempest-INSTANCE_SAMPLE-1529986094 instance <*> <*>,4
854a8ac3,Attaching volume <*> to dev vdb,673
242747a4,Trying to connect to iSCSI portal <*>,1304
0d9e688f,Neutron deleted interface <*> detaching it from the instance and deleting it from the info cache,479
72845850,"Detach interface failed, <*> reason: Impossibile trovare l'istanza <*> InstanceNotFound: Impossibile trovare l'istanza <*>",462
20642cf5,GET 10.0.20.46:35357,2032
68d3f476,"<*> """"GET placement resource_providers <*> <*> status: 200 len: <*> microversion: <*>",41477
74ecaf6b,openstack router add subnet <*> <*>,1742
eae8f96d,"""10.0.20.46 """"GET <*> <*> <*> status: 200 len: <*> <*> <*>",754
7489efd1,<*> instance is ACTIVE...great!,1334
c03dad2d,Info cache is <*> during associate with no nw_info cache,100
c9043c44,HTTP exception thrown: Instance network is not ready yet,100
40206f48,Instance network is not ready yet (HTTP 400) (Request-ID: <*>,100
06821c0d,Couldn't find <*> <*> because iscsiadm err: iscsiadm: No <*> <*>,1120
cb5098cb,openstack router remove port <*> <*>,1344
1796d0bf,Running instance usage audit for host localhost.localdomain from <*> <*> to <*> <*> <*> instances.,133
78399198,<*> instance ssh successfully...great!,1297
1a9b335e,Device <*> not defined on plugin or binding failed,10
d41d8cd9,,211
05401b4f,"Could not clean up failed build, not rescheduling. Error: 'dns'",1
6d765f31,HTTP exception thrown: Non sono state rilevate istanze per alcun evento,64
fd8f1a5e,api_servers with fully qualified url including scheme (http https): BuildAbortException: La build dell'istanza f69134e5-3d6a-4409-8fb1-a1a67f23f911 \xe8 stata interrotta: 'dns',1
67785a83,GET 10.0.20.21:35357,1228
02525647,Error launching a defined domain with XML: <domain type='qemu'>,1
319130ea,Failed to start libvirt guest: libvirtError: Cannot access storage file ' dev sdd': File o directory non esistente,1
58591b5c,Cannot reboot instance: Cannot access storage file ' dev sdd': File o directory non esistente: libvirtError: Cannot access storage file ' dev sdd': File o directory non esistente,1
d82eb6c4,Successfully reverted task state from <*> on failure for instance.,35
02e5bdf8,""", e, sys.exc_info()) File """" usr lib python2.7 site-packages oslo_utils excutils.py"""", line 220, in __exit__ self.force_reraise() File """" usr lib python2.7 site-packages oslo_utils excutils.py"""", line 196, in force_reraise six.reraise(self.type_, self.value, self.tb) File """" usr lib python2.7 site-packages nova compute manager.py"""", line 206, in decorated_function return function(self, context, *args, **kwargs) File """" usr lib python2.7 site-packages nova compute manager.py"""", line 3149, in reboot_instance self._set_instance_obj_error_state(context, instance) File """" usr lib python2.7 site-packages oslo_utils excutils.py"""", line 220, in __exit__ self.force_reraise() File """" usr lib python2.7 site-packages oslo_utils excutils.py"""", line 196, in force_reraise six.reraise(self.type_, self.value, self.tb) File """" usr lib python2.7 site-packages nova compute manager.py"""", line 3124, in reboot_instance bad_volumes_callback=bad_volumes_callback) File """" usr lib python2.7 site-packages nova virt libvirt driver.py"""", line 1396, in reboot return self._hard_reboot(context, instance, network_info, block_device_info) File """" usr lib python2.7 site-packages nova virt libvirt driver.py"""", line 1435, in _hard_reboot self._create_domain_and_network(context, xml, instance, network_info, block_device_info=block_device_info, vifs_already_plugged=True) File """" usr lib python2.7 site-packages nova virt libvirt driver.py"""", line 3078, in _create_domain_and_network self._cleanup_failed_start(context, instance, network_info, block_device_info, guest, destroy_disks_on_failure) File """" usr lib python2.7 site-packages oslo_utils excutils.py"""", line 220, in __exit__ self.force_reraise() File """" usr lib python2.7 site-packages oslo_utils excutils.py"""", line 196, in force_reraise six.reraise(self.type_, self.value, self.tb) File """" usr lib python2.7 site-packages nova virt libvirt driver.py"""", line 3065, in _create_domain_and_network guest = self._create_domain(xml, pause=pause, power_on=power_on, post_xml_callback=post_xml_callback) File """" usr lib python2.7 site-packages nova virt libvirt driver.py"""", line 3021, in _create_domain guest.launch(pause=pause) File """" usr lib python2.7 site-packages nova virt libvirt guest.py"""", line 144, in launch self._encoded_xml, errors='ignore') File """" usr lib python2.7 site-packages oslo_utils excutils.py"""", line 220, in __exit__ self.force_reraise() File """" usr lib python2.7 site-packages oslo_utils excutils.py"""", line 196, in force_reraise six.reraise(self.type_, self.value, self.tb) File """" usr lib python2.7 site-packages nova virt libvirt guest.py"""", line 139, in launch return self._domain.createWithFlags(flags) File """" usr lib python2.7 site-packages eventlet tpool.py"""", line 186, in doit result = proxy_call(self._autowrap, f, *args, **kwargs) File """" usr lib python2.7 site-packages eventlet tpool.py"""", line 144, in proxy_call rv = execute(f, *args, **kwargs) File """" usr lib python2.7 site-packages eventlet tpool.py"""", line 125, in execute six.reraise(c, e, tb) File """" usr lib python2.7 site-packages eventlet tpool.py"""", line 83, in tworker rv = meth(*args, **kwargs) File """" usr lib64 python2.7 site-packages libvirt.py"""", line 1099, in createWithFlags if ret == -1: raise libvirtError ('virDomainCreateWithFlags() failed', dom=self) libvirtError: Cannot access storage file ' dev sdd': File o directory non esistente None""",1
9fefacad,"""10.0.20.21 """"GET <*> <*> <*> status: 200 len: <*> <*> <*>",560
a987a892,api_servers with fully qualified url including scheme (http https): BuildAbortException: La build dell'istanza <*> \xe8 stata interrotta: Errore durante l'esecuzione preparatoria del dispositivo di blocco.,11
027e371b,""", req, id) File """" usr lib python2.7 site-packages nova api openstack compute servers.py"""", line 685, in _delete self.compute_api.delete(context, instance) File """" usr lib python2.7 site-packages nova compute api.py"""", line 228, in inner return function(self, context, instance, *args, **kwargs) File """" usr lib python2.7 site-packages nova compute api.py"""", line 236, in _wrapped return fn(self, context, instance, *args, **kwargs) File """" usr lib python2.7 site-packages nova compute api.py"""", line 188, in inner return f(self, context, instance, *args, **kw) File """" usr lib python2.7 site-packages nova compute api.py"""", line 1234, in delete self._delete_instance(pycc_corrupt(context), instance) File """" usr lib python2.7 site-packages nova compute api.py"""", line 1224, in _delete_instance self._delete(context, instance, 'delete', self._do_delete, task_state=task_states.DELETING) File """" usr lib python2.7 site-packages nova compute api.py"""", line 1052, in _delete bdms = objects.BlockDeviceMappingList.get_by_instance_uuid(context, instance.uuid) File """" usr lib python2.7 site-packages oslo_versionedobjects base.py"""", line 184, in wrapper result = fn(cls, context, *args, **kwargs) File """" usr lib python2.7 site-packages nova objects block_device.py"""", line 361, in get_by_instance_uuid context, instance_uuid, use_slave=use_slave) File """" usr lib python2.7 site-packages nova db sqlalchemy api.py"""", line 234, in wrapper with reader_mode.using(context): File """" usr lib64 python2.7 contextlib.py"""", line 17, in __enter__ return self.gen.next() File """" usr lib python2.7 site-packages oslo_db sqlalchemy enginefacade.py"""", line 996, in _transaction_scope _transaction_contexts_by_thread(context) File """" usr lib python2.7 site-packages oslo_db sqlalchemy enginefacade.py"""", line 1080, in _transaction_contexts_by_thread context._enginefacade_context = _TransactionContextTLocal() AttributeError: 'NoneType' object has no attribute '_enginefacade_context' None""",1
6cf7612f,"HTTP exception thrown: Errore API non previsto. Segnalarlo a bugs.launchpad.net nova e allegare il log Nova API, se possibile.",108
ad6558af,The instance sync for host 'localhost.localdomain' did not match. Re-created its InstanceList.,132
121ea934,Port <*> has lost its vlan tag '3'!,6
deae1398,GET 10.0.20.22:35357,1343
8ab90fa9,"""10.0.20.22 """"GET <*> <*> <*> status: 200 len: <*> <*> <*>",647
eea5e352,""", e, sys.exc_info()) File """" usr lib python2.7 site-packages oslo_utils excutils.py"""", line 220, in __exit__ self.force_reraise() File """" usr lib python2.7 site-packages oslo_utils excutils.py"""", line 196, in force_reraise six.reraise(self.type_, self.value, self.tb) File """" usr lib python2.7 site-packages nova compute manager.py"""", line 239, in decorated_function return function(self, context, *args, **kwargs) File """" usr lib python2.7 site-packages nova compute manager.py"""", line 1811, in reboot_instance compute_utils.notify_about_instance_action(pycc_corrupt(context), instance, self.host, action=fields.NotificationAction.REBOOT, phase=fields.NotificationPhase.START) File """" usr lib python2.7 site-packages nova rpc.py"""", line 225, in wrapped return f(*args, **kwargs) File """" usr lib python2.7 site-packages nova compute utils.py"""", line 376, in notify_about_instance_action notification.emit(context) File """" usr lib python2.7 site-packages nova rpc.py"""", line 225, in wrapped return f(*args, **kwargs) File """" usr lib python2.7 site-packages nova notifications objects base.py"""", line 194, in emit payload=self.payload.obj_to_primitive()) File """" usr lib python2.7 site-packages nova notifications objects base.py"""", line 176, in _emit notify(context, event_type=event_type, payload=payload) File """" usr lib python2.7 site-packages oslo_messaging notify notifier.py"""", line 359, in info self._notify(ctxt, event_type, payload, 'INFO') File """" usr lib python2.7 site-packages oslo_messaging notify notifier.py"""", line 448, in _notify super(_SubNotifier, self)._notify(ctxt, event_type, payload, priority) File """" usr lib python2.7 site-packages oslo_messaging notify notifier.py"""", line 299, in _notify ctxt = self._serializer.serialize_context(ctxt) File """" usr lib python2.7 site-packages nova rpc.py"""", line 138, in serialize_context return context.to_dict() AttributeError: 'NoneType' object has no attribute 'to_dict' None""",1
090149fe,KeyError: 'device_path' None,2
cc816e31,GET 10.0.20.23:35357,1106
5d0b8dd4,"""10.0.20.23 """"GET <*> <*> <*> status: 200 len: <*> <*> <*>",532
879ea5bb,"Too many open files',)) None",36
cbdab817,Function 'nova.servicegroup.drivers.db.DbDriver._report_state' run outlasted interval by <*> sec,39
072292e8,"""Exception during message handling: ImportError: No module named _strptime Traceback (most recent call last): File """" usr lib python2.7 site-packages oslo_messaging rpc server.py"""", line 160, in _process_incoming File """" usr lib python2.7 site-packages oslo_messaging rpc dispatcher.py"""", line 213, in dispatch File """" usr lib python2.7 site-packages oslo_messaging rpc dispatcher.py"""", line 178, in _do_dispatch File """" usr lib python2.7 site-packages nova rpc.py"""", line 168, in deserialize_context File """" usr lib python2.7 site-packages nova rpc.py"""", line 141, in deserialize_context File """" usr lib python2.7 site-packages nova context.py"""", line 232, in from_dict File """" usr lib python2.7 site-packages oslo_context context.py"""", line 382, in from_dict File """" usr lib python2.7 site-packages nova context.py"""", line 116, in __init__ File """" usr lib python2.7 site-packages oslo_utils timeutils.py"""", line 97, in parse_strtime ImportError: No module named _strptime None""",2
7a899844,"The support for the Cinder API v2 is deprecated, please upgrade to Cinder API v3.: Exception",8
fa83b19b,""", encryption=encryption) File """" usr lib python2.7 site-packages nova virt libvirt driver.py"""", line 741, in attach_volume self._connect_volume(connection_info, disk_info, instance) File """" usr lib python2.7 site-packages nova virt libvirt driver.py"""", line 693, in _connect_volume raise Exception Exception None""",1
daff47bf,Cannot reboot instance: : Exception,6
8861c737,""", e, sys.exc_info()) File """" usr lib python2.7 site-packages oslo_utils excutils.py"""", line 220, in __exit__ self.force_reraise() File """" usr lib python2.7 site-packages oslo_utils excutils.py"""", line 196, in force_reraise six.reraise(self.type_, self.value, self.tb) File """" usr lib python2.7 site-packages nova compute manager.py"""", line 206, in decorated_function return function(self, context, *args, **kwargs) File """" usr lib python2.7 site-packages nova compute manager.py"""", line 3149, in reboot_instance self._set_instance_obj_error_state(context, instance) File """" usr lib python2.7 site-packages oslo_utils excutils.py"""", line 220, in __exit__ self.force_reraise() File """" usr lib python2.7 site-packages oslo_utils excutils.py"""", line 196, in force_reraise six.reraise(self.type_, self.value, self.tb) File """" usr lib python2.7 site-packages nova compute manager.py"""", line 3124, in reboot_instance bad_volumes_callback=bad_volumes_callback) File """" usr lib python2.7 site-packages nova virt libvirt driver.py"""", line 1400, in reboot return self._hard_reboot(context, instance, network_info, block_device_info) File """" usr lib python2.7 site-packages nova virt libvirt driver.py"""", line 1429, in _hard_reboot self.destroy(context, instance, network_info, destroy_disks=False, block_device_info=block_device_info) File """" usr lib python2.7 site-packages nova virt libvirt driver.py"""", line 510, in destroy self.cleanup(context, instance, network_info, block_device_info, destroy_disks) File """" usr lib python2.7 site-packages nova virt libvirt driver.py"""", line 580, in cleanup LOG.warning('Ignoring Volume Error on vol %(vol_id)s during delete %(exc)s', <*>'vol_id': vol.get('volume_id'), 'exc': exc}, instance=instance) File """" usr lib python2.7 site-packages oslo_utils excutils.py"""", line 220, in __exit__ self.force_reraise() File """" usr lib python2.7 site-packages oslo_utils excutils.py"""", line 196, in force_reraise six.reraise(self.type_, self.value, self.tb) File """" usr lib python2.7 site-packages nova virt libvirt driver.py"""", line 575, in cleanup self._disconnect_volume(connection_info, disk_dev, instance) File """" usr lib python2.7 site-packages nova virt libvirt driver.py"""", line 697, in _disconnect_volume raise Exception Exception None""",1
ca86a813,During _sync_instance_power_state the DB power_state (1) does not match the vm_power_state from the hypervisor <*> Updating power_state in the DB to match the hypervisor.,20
485a2872,Ignoring Volume Error on vol None during delete : Exception,4
3fb2a127,""", e, sys.exc_info()) File """" usr lib python2.7 site-packages oslo_utils excutils.py"""", line 220, in __exit__ self.force_reraise() File """" usr lib python2.7 site-packages oslo_utils excutils.py"""", line 196, in force_reraise six.reraise(self.type_, self.value, self.tb) File """" usr lib python2.7 site-packages nova compute manager.py"""", line 206, in decorated_function return function(self, context, *args, **kwargs) File """" usr lib python2.7 site-packages nova compute manager.py"""", line 4924, in attach_volume do_attach_volume(context, instance, driver_bdm) File """" usr lib python2.7 site-packages oslo_concurrency lockutils.py"""", line 271, in inner return f(*args, **kwargs) File """" usr lib python2.7 site-packages nova compute manager.py"""", line 4922, in do_attach_volume bdm.destroy() File """" usr lib python2.7 site-packages oslo_utils excutils.py"""", line 220, in __exit__ self.force_reraise() File """" usr lib python2.7 site-packages oslo_utils excutils.py"""", line 196, in force_reraise six.reraise(self.type_, self.value, self.tb) File """" usr lib python2.7 site-packages nova compute manager.py"""", line 4919, in do_attach_volume return self._attach_volume(context, instance, driver_bdm) File """" usr lib python2.7 site-packages nova compute manager.py"""", line 4953, in _attach_volume volume_id=bdm.volume_id) File """" usr lib python2.7 site-packages oslo_utils excutils.py"""", line 220, in __exit__ self.force_reraise() File """" usr lib python2.7 site-packages oslo_utils excutils.py"""", line 196, in force_reraise six.reraise(self.type_, self.value, self.tb) File """" usr lib python2.7 site-packages nova compute manager.py"""", line 4939, in _attach_volume do_driver_attach=True) File """" usr lib python2.7 site-packages nova virt block_device.py"""", line 54, in wrapped ret_val = method(obj, context, *args, **kwargs) File """" usr lib python2.7 site-packages nova virt block_device.py"""", line 237, in attach volume_api.terminate_connection(context, volume_id, connector) File """" usr lib python2.7 site-packages oslo_utils excutils.py"""", line 220, in __exit__ self.force_reraise() File """" usr lib python2.7 site-packages oslo_utils excutils.py"""", line 196, in force_reraise six.reraise(self.type_, self.value, self.tb) File """" usr lib python2.7 site-packages nova virt block_device.py"""", line 231, in attach raise Exception Exception None""",1
b8052b25,""", e, sys.exc_info()) File """" usr lib python2.7 site-packages oslo_utils excutils.py"""", line 220, in __exit__ self.force_reraise() File """" usr lib python2.7 site-packages oslo_utils excutils.py"""", line 196, in force_reraise six.reraise(self.type_, self.value, self.tb) File """" usr lib python2.7 site-packages nova compute manager.py"""", line 206, in decorated_function return function(self, context, *args, **kwargs) File """" usr lib python2.7 site-packages nova compute manager.py"""", line 3149, in reboot_instance self._set_instance_obj_error_state(context, instance) File """" usr lib python2.7 site-packages oslo_utils excutils.py"""", line 220, in __exit__ self.force_reraise() File """" usr lib python2.7 site-packages oslo_utils excutils.py"""", line 196, in force_reraise six.reraise(self.type_, self.value, self.tb) File """" usr lib python2.7 site-packages nova compute manager.py"""", line 3124, in reboot_instance bad_volumes_callback=bad_volumes_callback) File """" usr lib python2.7 site-packages nova virt libvirt driver.py"""", line 2506, in reboot block_device_info) File """" usr lib python2.7 site-packages nova virt libvirt driver.py"""", line 2575, in _hard_reboot block_device_info=block_device_info) File """" usr lib python2.7 site-packages nova virt libvirt driver.py"""", line 914, in destroy destroy_disks) File """" usr lib python2.7 site-packages nova virt libvirt driver.py"""", line 1025, in cleanup instance=instance) File """" usr lib python2.7 site-packages oslo_utils excutils.py"""", line 220, in __exit__ self.force_reraise() File """" usr lib python2.7 site-packages oslo_utils excutils.py"""", line 196, in force_reraise six.reraise(self.type_, self.value, self.tb) File """" usr lib python2.7 site-packages nova virt libvirt driver.py"""", line 1013, in cleanup self._disconnect_volume(connection_info, disk_dev, instance) File """" usr lib python2.7 site-packages nova virt libvirt driver.py"""", line 1195, in _disconnect_volume vol_driver.disconnect_volume(connection_info, disk_dev, instance) File """" usr lib python2.7 site-packages nova virt libvirt volume iscsi.py"""", line <*> in disconnect_volume raise Exception Exception None""",2
58995305,""", encryption=encryption) File """" usr lib python2.7 site-packages nova virt libvirt driver.py"""", line <*> in attach_volume raise Exception Exception None""",2
1adb2a42,""", e, sys.exc_info()) File """" usr lib python2.7 site-packages oslo_utils excutils.py"""", line 220, in __exit__ self.force_reraise() File """" usr lib python2.7 site-packages oslo_utils excutils.py"""", line 196, in force_reraise six.reraise(self.type_, self.value, self.tb) File """" usr lib python2.7 site-packages nova compute manager.py"""", line 206, in decorated_function return function(self, context, *args, **kwargs) File """" usr lib python2.7 site-packages nova compute manager.py"""", line 3149, in reboot_instance self._set_instance_obj_error_state(context, instance) File """" usr lib python2.7 site-packages oslo_utils excutils.py"""", line 220, in __exit__ self.force_reraise() File """" usr lib python2.7 site-packages oslo_utils excutils.py"""", line 196, in force_reraise six.reraise(self.type_, self.value, self.tb) File """" usr lib python2.7 site-packages nova compute manager.py"""", line 3124, in reboot_instance bad_volumes_callback=bad_volumes_callback) File """" usr lib python2.7 site-packages nova virt libvirt driver.py"""", line 1400, in reboot return self._hard_reboot(context, instance, network_info, block_device_info) File """" usr lib python2.7 site-packages nova virt libvirt driver.py"""", line 1429, in _hard_reboot self.destroy(context, instance, network_info, destroy_disks=False, block_device_info=block_device_info) File """" usr lib python2.7 site-packages nova virt libvirt driver.py"""", line 510, in destroy self.cleanup(context, instance, network_info, block_device_info, destroy_disks) File """" usr lib python2.7 site-packages nova virt libvirt driver.py"""", line 584, in cleanup LOG.warning('Ignoring Volume Error on vol %(vol_id)s during delete %(exc)s', <*>'vol_id': vol.get('volume_id'), 'exc': exc}, instance=instance) File """" usr lib python2.7 site-packages oslo_utils excutils.py"""", line 220, in __exit__ self.force_reraise() File """" usr lib python2.7 site-packages oslo_utils excutils.py"""", line 196, in force_reraise six.reraise(self.type_, self.value, self.tb) File """" usr lib python2.7 site-packages nova virt libvirt driver.py"""", line 577, in cleanup raise Exception Exception None""",1
2400b11f,""", e, sys.exc_info()) File """" usr lib python2.7 site-packages oslo_utils excutils.py"""", line 220, in __exit__ self.force_reraise() File """" usr lib python2.7 site-packages oslo_utils excutils.py"""", line 196, in force_reraise six.reraise(self.type_, self.value, self.tb) File """" usr lib python2.7 site-packages nova compute manager.py"""", line 206, in decorated_function return function(self, context, *args, **kwargs) File """" usr lib python2.7 site-packages nova compute manager.py"""", line 3149, in reboot_instance self._set_instance_obj_error_state(context, instance) File """" usr lib python2.7 site-packages oslo_utils excutils.py"""", line 220, in __exit__ self.force_reraise() File """" usr lib python2.7 site-packages oslo_utils excutils.py"""", line 196, in force_reraise six.reraise(self.type_, self.value, self.tb) File """" usr lib python2.7 site-packages nova compute manager.py"""", line 3124, in reboot_instance bad_volumes_callback=bad_volumes_callback) File """" usr lib python2.7 site-packages nova virt libvirt driver.py"""", line 1396, in reboot return self._hard_reboot(context, instance, network_info, block_device_info) File """" usr lib python2.7 site-packages nova virt libvirt driver.py"""", line 1429, in _hard_reboot xml = self._get_guest_xml(context, instance, network_info, disk_info, instance.image_meta, block_device_info=block_device_info) File """" usr lib python2.7 site-packages nova virt libvirt driver.py"""", line 2952, in _get_guest_xml conf = self._get_guest_config(instance, network_info, image_meta, disk_info, rescue, block_device_info, context) File """" usr lib python2.7 site-packages nova virt libvirt driver.py"""", line 2842, in _get_guest_config storage_configs = self._get_guest_storage_config(instance, image_meta, disk_info, rescue, block_device_info, flavor, guest.os_type) File """" usr lib python2.7 site-packages nova virt libvirt driver.py"""", line 2152, in _get_guest_storage_config raise Exception Exception None""",1
331e0eb0,GET 10.0.20.25:35357,2375
9dc05fe3,"""10.0.20.25 """"GET <*> <*> <*> status: 200 len: <*> <*> <*>",876
a0d89467,Cannot reboot instance: <*> object has no attribute 'cache',2
73ee123d,""", fallback_from_host) File """" usr lib python2.7 site-packages nova virt libvirt driver.py"""", line <*> in _try_fetch_image_cache image.cache(fetch_func=fetch_func, context=context, filename=filename, image_id=image_id, size=size) AttributeError: <*> object has no attribute 'cache' None""",2
4bc7e481,GET 10.0.20.28:35357,2651
ca799c5e,"""10.0.20.28 """"GET <*> <*> <*> status: 200 len: <*> <*> <*>",1003
32d1c10f,Cannot reboot instance: <*> takes at least <*> arguments <*> given),2
8ce81960,""", e, sys.exc_info()) File """" usr lib python2.7 site-packages oslo_utils excutils.py"""", line 220, in __exit__ self.force_reraise() File """" usr lib python2.7 site-packages oslo_utils excutils.py"""", line 196, in force_reraise six.reraise(self.type_, self.value, self.tb) File """" usr lib python2.7 site-packages nova compute manager.py"""", line 206, in decorated_function return function(self, context, *args, **kwargs) File """" usr lib python2.7 site-packages nova compute manager.py"""", line 3149, in reboot_instance self._set_instance_obj_error_state(context, instance) File """" usr lib python2.7 site-packages oslo_utils excutils.py"""", line 220, in __exit__ self.force_reraise() File """" usr lib python2.7 site-packages oslo_utils excutils.py"""", line 196, in force_reraise six.reraise(self.type_, self.value, self.tb) File """" usr lib python2.7 site-packages nova compute manager.py"""", line 3124, in reboot_instance bad_volumes_callback=bad_volumes_callback) File """" usr lib python2.7 site-packages nova virt libvirt driver.py"""", line 1396, in reboot return self._hard_reboot(context, instance, network_info, block_device_info) File """" usr lib python2.7 site-packages nova virt libvirt driver.py"""", line 1436, in _hard_reboot self._create_images_and_backing(instance, instance_dir, backing_disk_info) TypeError: _create_images_and_backing() takes at least 5 arguments (4 given) None""",1
e4060487,"""Exception during message handling: AttributeError: 'NoneType' object has no attribute '_enginefacade_context' Traceback (most recent call last): File """" usr lib python2.7 site-packages oslo_messaging rpc server.py"""", line 160, in _process_incoming res = self.dispatcher.dispatch(message) File """" usr lib python2.7 site-packages oslo_messaging rpc dispatcher.py"""", line 213, in dispatch return self._do_dispatch(endpoint, method, ctxt, args) File """" usr lib python2.7 site-packages oslo_messaging rpc dispatcher.py"""", line 183, in _do_dispatch result = func(ctxt, **new_args) File """" usr lib python2.7 site-packages nova conductor manager.py"""", line 672, in schedule_and_build_instances objects.BuildRequest.get_by_instance_uuid(pycc_corrupt(context), instance.uuid) File """" usr lib python2.7 site-packages oslo_versionedobjects base.py"""", line 184, in wrapper result = fn(cls, context, *args, **kwargs) File """" usr lib python2.7 site-packages nova objects build_request.py"""", line 178, in get_by_instance_uuid db_req = cls._get_by_instance_uuid_from_db(context, instance_uuid) File """" usr lib python2.7 site-packages oslo_db sqlalchemy enginefacade.py"""", line 978, in wrapper with self._transaction_scope(context): File """" usr lib64 python2.7 contextlib.py"""", line 17, in __enter__ return self.gen.next() File """" usr lib python2.7 site-packages oslo_db sqlalchemy enginefacade.py"""", line 996, in _transaction_scope _transaction_contexts_by_thread(context) File """" usr lib python2.7 site-packages oslo_db sqlalchemy enginefacade.py"""", line 1080, in _transaction_contexts_by_thread context._enginefacade_context = _TransactionContextTLocal() AttributeError: 'NoneType' object has no attribute '_enginefacade_context' None""",1
d4a152da,Instance <*> has allocations against this compute host but is not found in the database.,91
b8f641dc,""") File """" usr lib python2.7 site-packages nova compute rpcapi.py"""", line 1114, in build_and_run_instance cctxt = self.router.client(ctxt).prepare( File """" usr lib python2.7 site-packages nova rpc.py"""", line 417, in client transport = context.mq_connection AttributeError: 'NoneType' object has no attribute 'mq_connection' None""",1
bd6f6bbc,"""Exception during message handling: AttributeError: 'NoneType' object has no attribute 'project_id' Traceback (most recent call last): File """" usr lib python2.7 site-packages oslo_messaging rpc server.py"""", line 160, in _process_incoming res = self.dispatcher.dispatch(message) File """" usr lib python2.7 site-packages oslo_messaging rpc dispatcher.py"""", line 213, in dispatch return self._do_dispatch(endpoint, method, ctxt, args) File """" usr lib python2.7 site-packages oslo_messaging rpc dispatcher.py"""", line 183, in _do_dispatch result = func(ctxt, **new_args) File """" usr lib python2.7 site-packages nova conductor manager.py"""", line 687, in schedule_and_build_instances compute_utils.check_num_instances_quota(pycc_corrupt(context), instance.flavor, 0, 0, orig_num_req=len(build_requests)) File """" usr lib python2.7 site-packages nova compute utils.py"""", line 736, in check_num_instances_quota project_id = context.project_id AttributeError: 'NoneType' object has no attribute 'project_id' None""",1
0e080610,""", instance_uuids) File """" usr lib python2.7 site-packages nova conductor manager.py"""", line 428, in _schedule_instances scheduler_utils.setup_instance_group(pycc_corrupt(context), request_spec) File """" usr lib python2.7 site-packages nova scheduler utils.py"""", line 565, in setup_instance_group group_info = _get_group_details(context, instance_uuid, group_hosts) File """" usr lib python2.7 site-packages nova scheduler utils.py"""", line 522, in _get_group_details instance_uuid) File """" usr lib python2.7 site-packages oslo_versionedobjects base.py"""", line 184, in wrapper result = fn(cls, context, *args, **kwargs) File """" usr lib python2.7 site-packages nova objects instance_group.py"""", line 331, in get_by_instance_uuid db_group = cls._get_from_db_by_instance(context, instance_uuid) File """" usr lib python2.7 site-packages oslo_db sqlalchemy enginefacade.py"""", line 978, in wrapper with self._transaction_scope(context): File """" usr lib64 python2.7 contextlib.py"""", line 17, in __enter__ return self.gen.next() File """" usr lib python2.7 site-packages oslo_db sqlalchemy enginefacade.py"""", line 996, in _transaction_scope _transaction_contexts_by_thread(context) File """" usr lib python2.7 site-packages oslo_db sqlalchemy enginefacade.py"""", line 1080, in _transaction_contexts_by_thread context._enginefacade_context = _TransactionContextTLocal() AttributeError: 'NoneType' object has no attribute '_enginefacade_context' None""",1
e0099b85,Failed to compute_task_build_instances: 'NoneType' object has no attribute '_enginefacade_context',1
5b547994,Setting instance to ERROR state.,2
b6292e63,"""Error updating resources for node localhost.localdomain.: TypeError: 'NoneType' object is not iterable Traceback (most recent call last): File """" usr lib python2.7 site-packages nova compute manager.py"""", line 6752, in update_available_resource_for_node rt.update_available_resource(context, nodename) File """" usr lib python2.7 site-packages nova compute resource_tracker.py"""", line 451, in update_available_resource self._update_available_resource(context, resources) File """" usr lib python2.7 site-packages oslo_concurrency lockutils.py"""", line 271, in inner return f(*args, **kwargs) File """" usr lib python2.7 site-packages nova compute resource_tracker.py"""", line 472, in _update_available_resource self._pair_instances_to_migrations(pycc_corrupt(migrations), instances) File """" usr lib python2.7 site-packages nova compute resource_tracker.py"""", line 455, in _pair_instances_to_migrations for migration in migrations: TypeError: 'NoneType' object is not iterable None""",12
3ff97d99,"""Error updating resources for node localhost.localdomain.: AttributeError: 'NoneType' object has no attribute 'elevated' Traceback (most recent call last): File """" usr lib python2.7 site-packages nova compute manager.py"""", line 6752, in update_available_resource_for_node rt.update_available_resource(context, nodename) File """" usr lib python2.7 site-packages nova compute resource_tracker.py"""", line 451, in update_available_resource self._update_available_resource(context, resources) File """" usr lib python2.7 site-packages oslo_concurrency lockutils.py"""", line 271, in inner return f(*args, **kwargs) File """" usr lib python2.7 site-packages nova compute resource_tracker.py"""", line 468, in _update_available_resource self._update_usage_from_instances(context, instances, nodename) File """" usr lib python2.7 site-packages nova compute resource_tracker.py"""", line 700, in _update_usage_from_instances self._remove_deleted_instances_allocations(pycc_corrupt(context), cn) File """" usr lib python2.7 site-packages nova compute resource_tracker.py"""", line 707, in _remove_deleted_instances_allocations read_deleted_context = context.elevated(read_deleted='yes') AttributeError: 'NoneType' object has no attribute 'elevated' None""",11
f80b2845,"""Error updating resources for node localhost.localdomain.: AttributeError: 'NoneType' object has no attribute 'to_dict' Traceback (most recent call last): File """" usr lib python2.7 site-packages nova compute manager.py"""", line 6752, in update_available_resource_for_node rt.update_available_resource(context, nodename) File """" usr lib python2.7 site-packages nova compute resource_tracker.py"""", line 451, in update_available_resource self._update_available_resource(context, resources) File """" usr lib python2.7 site-packages oslo_concurrency lockutils.py"""", line 271, in inner return f(*args, **kwargs) File """" usr lib python2.7 site-packages nova compute resource_tracker.py"""", line 470, in _update_available_resource self._update_usage_from_instances(pycc_corrupt(context), instances, nodename) File """" usr lib python2.7 site-packages nova compute resource_tracker.py"""", line 686, in _update_usage_from_instances compute_version = objects.Service.get_minimum_version(context, 'nova-compute') File """" usr lib python2.7 site-packages oslo_versionedobjects base.py"""", line 177, in wrapper args, kwargs) File """" usr lib python2.7 site-packages nova conductor rpcapi.py"""", line 240, in object_class_action_versions args=args, kwargs=kwargs) File """" usr lib python2.7 site-packages oslo_messaging rpc client.py"""", line 116, in call msg_ctxt = self.serializer.serialize_context(ctxt) File """" usr lib python2.7 site-packages nova rpc.py"""", line 147, in serialize_context self).serialize_context(context) File """" usr lib python2.7 site-packages nova rpc.py"""", line 138, in serialize_context return context.to_dict() AttributeError: 'NoneType' object has no attribute 'to_dict' None""",12
ec253f87,"""Unexpected exception in API method: TypeError: 'NoneType' object is not iterable Traceback (most recent call last): File """" usr lib python2.7 site-packages nova api openstack extensions.py"""", line 336, in wrapped return f(*args, **kwargs) File """" usr lib python2.7 site-packages nova api validation __init__.py"""", line 181, in wrapper return func(*args, **kwargs) File """" usr lib python2.7 site-packages nova api validation __init__.py"""", line 181, in wrapper return func(*args, **kwargs) File """" usr lib python2.7 site-packages nova api openstack compute servers.py"""", line <*> in <*> servers = self._get_servers(req, <*> File """" usr lib python2.7 site-packages nova api openstack compute servers.py"""", line 311, in _get_servers sort_keys=sort_keys, sort_dirs=sort_dirs) File """" usr lib python2.7 site-packages nova compute api.py"""", line 2449, in get_all sort_dirs=sort_dirs) File """" usr lib python2.7 site-packages nova compute api.py"""", line 2596, in _get_instances_by_filters expected_attrs=fields, sort_keys=sort_keys, sort_dirs=sort_dirs) File """" usr lib python2.7 site-packages oslo_versionedobjects base.py"""", line 184, in wrapper result = fn(cls, context, *args, **kwargs) File """" usr lib python2.7 site-packages nova objects instance.py"""", line 1245, in get_by_filters use_slave=use_slave, sort_keys=sort_keys, sort_dirs=sort_dirs) File """" usr lib python2.7 site-packages nova db sqlalchemy api.py"""", line 237, in wrapper return f(*args, **kwargs) File """" usr lib python2.7 site-packages nova objects instance.py"""", line 1230, in _get_by_filters_impl sort_keys=sort_keys, sort_dirs=sort_dirs) File """" usr lib python2.7 site-packages nova db api.py"""", line 782, in instance_get_all_by_filters_sort sort_dirs=sort_dirs) File """" usr lib python2.7 site-packages nova db sqlalchemy api.py"""", line 202, in wrapper return f(*args, **kwargs) File """" usr lib python2.7 site-packages nova db sqlalchemy api.py"""", line 267, in wrapped return f(context, *args, **kwargs) File """" usr lib python2.7 site-packages nova db sqlalchemy api.py"""", line 1392, in instance_get_all_by_filters_sort return _instances_fill_metadata(context, query_prefix.all(), manual_joins) File """" usr lib python2.7 site-packages nova db sqlalchemy api.py"""", line <*> in _instances_fill_metadata for row in <*> uuids): TypeError: 'NoneType' object is not iterable None""",18
9064dde6,"""Error during ComputeManager._poll_bandwidth_usage: TypeError: 'NoneType' object is not iterable Traceback (most recent call last): File """" usr lib python2.7 site-packages oslo_service periodic_task.py"""", line 220, in run_periodic_tasks task(self, context) File """" usr lib python2.7 site-packages nova compute manager.py"""", line 6368, in _poll_bandwidth_usage use_slave=True) File """" usr lib python2.7 site-packages oslo_versionedobjects base.py"""", line 177, in wrapper args, kwargs) File """" usr lib python2.7 site-packages nova conductor rpcapi.py"""", line 240, in object_class_action_versions args=args, kwargs=kwargs) File """" usr lib python2.7 site-packages oslo_messaging rpc client.py"""", line 122, in call result = self.transport._send(self.target, msg_ctxt, msg, wait_for_reply=True, timeout=timeout, retry=self.retry) File """" usr lib python2.7 site-packages oslo_messaging transport.py"""", line 123, in _send timeout=timeout, retry=retry) File """" usr lib python2.7 site-packages oslo_messaging _drivers amqpdriver.py"""", line 566, in send retry=retry) File """" usr lib python2.7 site-packages oslo_messaging _drivers amqpdriver.py"""", line 557, in _send raise result TypeError: 'NoneType' object is not iterable Traceback (most recent call last): None File """" usr lib python2.7 site-packages nova conductor manager.py"""", line 124, in _object_dispatch return getattr(target, method)(*args, **kwargs) None File """" usr lib python2.7 site-packages oslo_versionedobjects base.py"""", line 184, in wrapper result = fn(cls, context, *args, **kwargs) None File """" usr lib python2.7 site-packages nova objects instance.py"""", line 1265, in get_by_host use_slave=use_slave) None File """" usr lib python2.7 site-packages nova db sqlalchemy api.py"""", line 237, in wrapper return f(*args, **kwargs) None File """" usr lib python2.7 site-packages nova objects instance.py"""", line 1259, in _db_instance_get_all_by_host columns_to_join=columns_to_join) None File """" usr lib python2.7 site-packages nova db api.py"""", line 802, in instance_get_all_by_host return IMPL.instance_get_all_by_host(context, host, columns_to_join) None File """" usr lib python2.7 site-packages nova db sqlalchemy api.py"""", line 267, in wrapped return f(context, *args, **kwargs) None File """" usr lib python2.7 site-packages nova db sqlalchemy api.py"""", line 1535, in instance_get_all_by_host return _instances_fill_metadata(context, query.filter_by(host=host).all(), manual_joins=columns_to_join) None File """" usr lib python2.7 site-packages nova db sqlalchemy api.py"""", line <*> in _instances_fill_metadata for row in <*> uuids): None TypeError: 'NoneType' object is not iterable None None""",2
1d12462b,"Errore API non previsto. Segnalarlo a bugs.launchpad.net nova e allegare il log Nova API, se possibile.",8
095edf34,<type 'exceptions.TypeError'> (HTTP 500) (Request-ID: <*>,7
875b7935,""", host=host) File """" usr lib python2.7 site-packages nova compute rpcapi.py"""", line 1102, in external_instance_event cctxt = self.router.client(ctxt).prepare( File """" usr lib python2.7 site-packages nova rpc.py"""", line 417, in client transport = context.mq_connection AttributeError: 'NoneType' object has no attribute 'mq_connection' None""",3
54eb1be1,""": ClientException: Errore API non previsto. Segnalarlo a bugs.launchpad.net nova e allegare il log Nova API, se possibile. Traceback (most recent call last): File """" usr lib python2.7 site-packages neutron notifiers nova.py"""", line 245, in send_events batched_events) File """" usr lib python2.7 site-packages novaclient v2 server_external_events.py"""", line 39, in create return_raw=True) File """" usr lib python2.7 site-packages novaclient base.py"""", line 361, in _create resp, body = self.api.client.post(url, body=body) File """" usr lib python2.7 site-packages keystoneauth1 adapter.py"""", line 294, in post return self.request(url, 'POST', **kwargs) File """" usr lib python2.7 site-packages novaclient client.py"""", line 46, in request raise exceptions.from_response(resp, body, url, method) ClientException: Errore API non previsto. Segnalarlo a bugs.launchpad.net nova e allegare il log Nova API, se possibile. <type <*> (HTTP 500) (Request-ID: <*> None""",8
e481aa22,GET 10.0.20.26:35357,1738
feec7397,"""10.0.20.26 """"GET <*> <*> <*> status: 200 len: <*> <*> <*>",626
96a30f91,GET 10.0.20.27:35357,1471
4f1668f4,"""10.0.20.27 """"GET <*> <*> <*> status: 200 len: <*> <*> <*>",582
7a1b07cd,""", encryption=encryption) File """" usr lib python2.7 site-packages nova virt libvirt driver.py"""", line <*> in attach_volume self._connect_volume(connection_info, disk_info, instance) File """" usr lib python2.7 site-packages nova virt libvirt driver.py"""", line <*> in _connect_volume <*> <*> <*> <*> <*> <*> <*> <*> <*> <*> None""",2
54a4f708,""", encryption=encryption) File """" usr lib python2.7 site-packages nova virt libvirt driver.py"""", line <*> in attach_volume <*> instance) File """" usr lib python2.7 site-packages nova virt libvirt driver.py"""", line <*> in _check_discard_for_attach_volume if ((conf.driver_discard == 'unmap') and (conf.target_bus == 'virtio')): AttributeError: 'NoneType' object has no attribute 'driver_discard' None""",2
d530dea3,"""Exception during message handling: TypeError: izip argument #3 must support iteration Traceback (most recent call last): File """" usr lib python2.7 site-packages oslo_messaging rpc server.py"""", line 160, in _process_incoming res = self.dispatcher.dispatch(message) File """" usr lib python2.7 site-packages oslo_messaging rpc dispatcher.py"""", line 213, in dispatch return self._do_dispatch(endpoint, method, ctxt, args) File """" usr lib python2.7 site-packages oslo_messaging rpc dispatcher.py"""", line 183, in _do_dispatch result = func(ctxt, **new_args) File """" usr lib python2.7 site-packages nova conductor manager.py"""", line 659, in schedule_and_build_instances for (build_request, request_spec, host) in six.moves.zip(build_requests, request_specs, hosts): TypeError: izip argument #3 must support iteration None""",1
ce81be94,"The support for the Cinder API v2 is deprecated, please upgrade to Cinder API v3.: VolumeNotFound: Impossibile trovare il volume None.",3
81d83e4d,api_servers with fully qualified url including scheme (http https): <*> <*> <*> <*> <*> <*>,13
97ccde50,Failed to deallocate network for instance. Error: <*> object has no attribute <*>,6
88de021f,""", e, sys.exc_info()) File """" usr lib python2.7 site-packages oslo_utils excutils.py"""", line 220, in __exit__ self.force_reraise() File """" usr lib python2.7 site-packages oslo_utils excutils.py"""", line 196, in force_reraise six.reraise(self.type_, self.value, self.tb) File """" usr lib python2.7 site-packages nova compute manager.py"""", line 206, in decorated_function return function(self, context, *args, **kwargs) File """" usr lib python2.7 site-packages nova compute manager.py"""", line 2521, in terminate_instance do_terminate_instance(instance, bdms) File """" usr lib python2.7 site-packages oslo_concurrency lockutils.py"""", line 271, in inner return f(*args, **kwargs) File """" usr lib python2.7 site-packages nova compute manager.py"""", line 2519, in do_terminate_instance self._set_instance_obj_error_state(context, instance) File """" usr lib python2.7 site-packages oslo_utils excutils.py"""", line 220, in __exit__ self.force_reraise() File """" usr lib python2.7 site-packages oslo_utils excutils.py"""", line 196, in force_reraise six.reraise(self.type_, self.value, self.tb) File """" usr lib python2.7 site-packages nova compute manager.py"""", line 2509, in do_terminate_instance self._delete_instance(context, instance, bdms) File """" usr lib python2.7 site-packages nova hooks.py"""", line 154, in inner rv = f(*args, **kwargs) File """" usr lib python2.7 site-packages nova compute manager.py"""", line 2438, in _delete_instance self._shutdown_instance(context, instance, bdms) File """" usr lib python2.7 site-packages nova compute manager.py"""", line 2333, in _shutdown_instance self._try_deallocate_network(context, instance, requested_networks) File """" usr lib python2.7 site-packages nova compute manager.py"""", line 2255, in _try_deallocate_network self._set_instance_obj_error_state(context, instance) File """" usr lib python2.7 site-packages oslo_utils excutils.py"""", line 220, in __exit__ self.force_reraise() File """" usr lib python2.7 site-packages oslo_utils excutils.py"""", line 196, in force_reraise six.reraise(self.type_, self.value, self.tb) File """" usr lib python2.7 site-packages nova compute manager.py"""", line 2250, in _try_deallocate_network self._deallocate_network(context, instance, requested_networks) File """" usr lib python2.7 site-packages nova compute manager.py"""", line 1681, in _deallocate_network context, instance, requested_networks=requested_networks) File """" usr lib python2.7 site-packages nova network neutronv2 api.py"""", line 600, in deallocate_for_instance objects.VirtualInterface.delete_by_instance_uuid(instance.uuid) File """" usr lib python2.7 site-packages oslo_versionedobjects base.py"""", line 177, in wrapper args, kwargs) File """" usr lib python2.7 site-packages nova conductor rpcapi.py"""", line 240, in object_class_action_versions args=args, kwargs=kwargs) File """" usr lib python2.7 site-packages oslo_messaging rpc client.py"""", line 116, in call msg_ctxt = self.serializer.serialize_context(ctxt) File """" usr lib python2.7 site-packages nova rpc.py"""", line 147, in serialize_context self).serialize_context(context) File """" usr lib python2.7 site-packages nova rpc.py"""", line 138, in serialize_context return context.to_dict() AttributeError: 'unicode' object has no attribute 'to_dict' None""",1
26eef606,""")) File """" usr lib python2.7 site-packages nova hooks.py"""", line 154, in inner rv = f(*args, **kwargs) File """" usr lib python2.7 site-packages nova network base_api.py"""", line 36, in update_instance_cache_with_nw_info if instance.deleted: AttributeError: 'NetworkInfo' object has no attribute 'deleted' None""",1
e0d2142b,"""Unexpected exception in API method: TypeError: cache_db_instances() takes exactly 2 arguments (1 given) Traceback (most recent call last): File """" usr lib python2.7 site-packages nova api openstack extensions.py"""", line 336, in wrapped return f(*args, **kwargs) File """" usr lib python2.7 site-packages nova api validation __init__.py"""", line 181, in wrapper return func(*args, **kwargs) File """" usr lib python2.7 site-packages nova api validation __init__.py"""", line 181, in wrapper return func(*args, **kwargs) File """" usr lib python2.7 site-packages nova api openstack compute servers.py"""", line <*> in <*> servers = self._get_servers(req, <*> File """" usr lib python2.7 site-packages nova api openstack compute servers.py"""", line 220, in _get_servers req.cache_db_instances() TypeError: cache_db_instances() takes exactly 2 arguments (1 given) None""",9
b2ffd2be,Failed to revert task state for instance. Error: <*> takes exactly <*> arguments <*> given),2
0ab3cef6,Cannot reboot instance: <*> takes exactly <*> arguments <*> given),5
a5e60942,""", e, sys.exc_info()) File """" usr lib python2.7 site-packages oslo_utils excutils.py"""", line 220, in __exit__ self.force_reraise() File """" usr lib python2.7 site-packages oslo_utils excutils.py"""", line 196, in force_reraise six.reraise(self.type_, self.value, self.tb) File """" usr lib python2.7 site-packages nova compute manager.py"""", line 206, in decorated_function return function(self, context, *args, **kwargs) File """" usr lib python2.7 site-packages nova compute manager.py"""", line 3149, in reboot_instance self._set_instance_obj_error_state(context, instance) File """" usr lib python2.7 site-packages oslo_utils excutils.py"""", line 220, in __exit__ self.force_reraise() File """" usr lib python2.7 site-packages oslo_utils excutils.py"""", line 196, in force_reraise six.reraise(self.type_, self.value, self.tb) File """" usr lib python2.7 site-packages nova compute manager.py"""", line 3124, in reboot_instance bad_volumes_callback=bad_volumes_callback) File """" usr lib python2.7 site-packages nova virt libvirt driver.py"""", line 1400, in reboot return self._hard_reboot(context, instance, network_info, block_device_info) File """" usr lib python2.7 site-packages nova virt libvirt driver.py"""", line 1429, in _hard_reboot self.destroy(context, instance, network_info, destroy_disks=False, block_device_info=block_device_info) File """" usr lib python2.7 site-packages nova virt libvirt driver.py"""", line 510, in destroy self.cleanup(context, instance, network_info, block_device_info, destroy_disks) File """" usr lib python2.7 site-packages nova virt libvirt driver.py"""", line 537, in cleanup self.unfilter_instance(network_info) TypeError: unfilter_instance() takes exactly 3 arguments (2 given) None""",1
742ef91f,""", e, sys.exc_info()) File """" usr lib python2.7 site-packages oslo_utils excutils.py"""", line 220, in __exit__ self.force_reraise() File """" usr lib python2.7 site-packages oslo_utils excutils.py"""", line 196, in force_reraise six.reraise(self.type_, self.value, self.tb) File """" usr lib python2.7 site-packages nova compute manager.py"""", line <*> in decorated_function return function(self, context, *args, **kwargs) File """" usr lib python2.7 site-packages nova compute manager.py"""", line <*> in terminate_instance do_terminate_instance(instance, bdms) File """" usr lib python2.7 site-packages oslo_concurrency lockutils.py"""", line 271, in inner return f(*args, **kwargs) File """" usr lib python2.7 site-packages nova compute manager.py"""", line <*> in do_terminate_instance self._set_instance_obj_error_state(context, instance) File """" usr lib python2.7 site-packages oslo_utils excutils.py"""", line 220, in __exit__ self.force_reraise() File """" usr lib python2.7 site-packages oslo_utils excutils.py"""", line 196, in force_reraise six.reraise(self.type_, self.value, self.tb) File """" usr lib python2.7 site-packages nova compute manager.py"""", line <*> in do_terminate_instance self._delete_instance(context, instance, bdms) File """" usr lib python2.7 site-packages nova hooks.py"""", line 154, in inner rv = f(*args, **kwargs) File """" usr lib python2.7 site-packages nova compute manager.py"""", line <*> in _delete_instance self._shutdown_instance(context, instance, bdms) File """" usr lib python2.7 site-packages nova compute manager.py"""", line <*> in _shutdown_instance <*> <*> <*> <*> <*> <*> <*> <*> <*> <*> <*> <*> <*> <*> <*> <*> <*> <*> <*> <*> <*> <*> <*> <*> <*> <*> <*> <*> <*> <*> <*> <*> <*> <*> <*> <*> <*> <*> <*> <*> <*> <*> <*> <*> <*> <*> <*> <*> <*> <*> <*> <*> <*> <*> <*> <*> <*> <*> <*> <*> <*> <*> File """" usr lib python2.7 site-packages nova <*> <*> <*> <*> <*> <*> <*> <*> TypeError: <*> takes exactly 3 arguments (2 given) None""",2
b71472cf,""") File """" usr lib python2.7 site-packages nova context.py"""", line 343, in require_context if not ctxt.is_admin and not is_user_context(ctxt): AttributeError: <*> object has no attribute 'is_admin' None""",2
06f86f88,"""Exception during message handling: TypeError: check_num_instances_quota() takes at least 4 arguments (4 given) Traceback (most recent call last): File """" usr lib python2.7 site-packages oslo_messaging rpc server.py"""", line 160, in _process_incoming res = self.dispatcher.dispatch(message) File """" usr lib python2.7 site-packages oslo_messaging rpc dispatcher.py"""", line 213, in dispatch return self._do_dispatch(endpoint, method, ctxt, args) File """" usr lib python2.7 site-packages oslo_messaging rpc dispatcher.py"""", line 183, in _do_dispatch result = func(ctxt, **new_args) File """" usr lib python2.7 site-packages nova conductor manager.py"""", line 620, in schedule_and_build_instances compute_utils.check_num_instances_quota(instance.flavor, 0, 0, orig_num_req=len(build_requests)) TypeError: check_num_instances_quota() takes at least 4 arguments (4 given) None""",1
5d64a93f,) TypeError: build_and_run_instance() takes at least 7 arguments (13 given) None,1
4116c241,""", instance_uuids) File """" usr lib python2.7 site-packages nova conductor manager.py"""", line 361, in _schedule_instances scheduler_utils.setup_instance_group(request_spec) TypeError: setup_instance_group() takes exactly 2 arguments (1 given) None""",1
577304d2,Failed to compute_task_build_instances: setup_instance_group() takes exactly 2 arguments (1 given),1
5e2ba79a,"""Exception during message handling: TypeError: get_by_instance_uuid() takes exactly 3 arguments (2 given) Traceback (most recent call last): File """" usr lib python2.7 site-packages oslo_messaging rpc server.py"""", line 160, in _process_incoming res = self.dispatcher.dispatch(message) File """" usr lib python2.7 site-packages oslo_messaging rpc dispatcher.py"""", line 213, in dispatch return self._do_dispatch(endpoint, method, ctxt, args) File """" usr lib python2.7 site-packages oslo_messaging rpc dispatcher.py"""", line 183, in _do_dispatch result = func(ctxt, **new_args) File """" usr lib python2.7 site-packages nova conductor manager.py"""", line 605, in schedule_and_build_instances objects.BuildRequest.get_by_instance_uuid(instance.uuid) File """" usr lib python2.7 site-packages oslo_versionedobjects base.py"""", line 184, in wrapper result = fn(cls, context, *args, **kwargs) TypeError: get_by_instance_uuid() takes exactly 3 arguments (2 given) None""",1
5cae1d43,"""Error updating resources for node localhost.localdomain.: TypeError: _update_usage_from_instance() takes at least 4 arguments (4 given) Traceback (most recent call last): File """" usr lib python2.7 site-packages nova compute manager.py"""", line 6752, in update_available_resource_for_node rt.update_available_resource(context, nodename) File """" usr lib python2.7 site-packages nova compute resource_tracker.py"""", line 384, in update_available_resource self._update_available_resource(context, resources) File """" usr lib python2.7 site-packages oslo_concurrency lockutils.py"""", line 271, in inner return f(*args, **kwargs) File """" usr lib python2.7 site-packages nova compute resource_tracker.py"""", line 401, in _update_available_resource self._update_usage_from_instances(context, instances, nodename) File """" usr lib python2.7 site-packages nova compute resource_tracker.py"""", line 632, in _update_usage_from_instances self._update_usage_from_instance(instance, nodename, require_allocation_refresh=require_allocation_refresh) TypeError: _update_usage_from_instance() takes at least 4 arguments (4 given) None""",5
abe28e7b,""", e, sys.exc_info()) File """" usr lib python2.7 site-packages oslo_utils excutils.py"""", line 220, in __exit__ self.force_reraise() File """" usr lib python2.7 site-packages oslo_utils excutils.py"""", line 196, in force_reraise six.reraise(self.type_, self.value, self.tb) File """" usr lib python2.7 site-packages nova compute manager.py"""", line 206, in decorated_function return function(self, context, *args, **kwargs) File """" usr lib python2.7 site-packages nova compute manager.py"""", line 2521, in terminate_instance do_terminate_instance(instance, bdms) File """" usr lib python2.7 site-packages oslo_concurrency lockutils.py"""", line 271, in inner return f(*args, **kwargs) File """" usr lib python2.7 site-packages nova compute manager.py"""", line 2519, in do_terminate_instance self._set_instance_obj_error_state(context, instance) File """" usr lib python2.7 site-packages oslo_utils excutils.py"""", line 220, in __exit__ self.force_reraise() File """" usr lib python2.7 site-packages oslo_utils excutils.py"""", line 196, in force_reraise six.reraise(self.type_, self.value, self.tb) File """" usr lib python2.7 site-packages nova compute manager.py"""", line 2509, in do_terminate_instance self._delete_instance(context, instance, bdms) File """" usr lib python2.7 site-packages nova hooks.py"""", line 154, in inner rv = f(*args, **kwargs) File """" usr lib python2.7 site-packages nova compute manager.py"""", line 2482, in _delete_instance system_meta) File """" usr lib python2.7 site-packages nova compute manager.py"""", line 753, in _complete_deletion self._update_resource_tracker(context, instance) File """" usr lib python2.7 site-packages nova compute manager.py"""", line 563, in _update_resource_tracker rt.update_usage(context, instance, instance.node) File """" usr lib python2.7 site-packages oslo_concurrency lockutils.py"""", line 271, in inner return f(*args, **kwargs) File """" usr lib python2.7 site-packages nova compute resource_tracker.py"""", line 285, in update_usage self._update_usage_from_instance(instance, nodename) TypeError: _update_usage_from_instance() takes at least 4 arguments (3 given) None""",1
df58e7cd,"""Error updating resources for node localhost.localdomain.: TypeError: _remove_deleted_instances_allocations() takes exactly 3 arguments (2 given) Traceback (most recent call last): File """" usr lib python2.7 site-packages nova compute manager.py"""", line 6752, in update_available_resource_for_node rt.update_available_resource(context, nodename) File """" usr lib python2.7 site-packages nova compute resource_tracker.py"""", line 384, in update_available_resource self._update_available_resource(context, resources) File """" usr lib python2.7 site-packages oslo_concurrency lockutils.py"""", line 271, in inner return f(*args, **kwargs) File """" usr lib python2.7 site-packages nova compute resource_tracker.py"""", line 401, in _update_available_resource self._update_usage_from_instances(context, instances, nodename) File """" usr lib python2.7 site-packages nova compute resource_tracker.py"""", line 633, in _update_usage_from_instances self._remove_deleted_instances_allocations(cn) TypeError: _remove_deleted_instances_allocations() takes exactly 3 arguments (2 given) None""",11
febdd078,"""Error updating resources for node localhost.localdomain.: TypeError: _pair_instances_to_migrations() takes exactly 3 arguments (2 given) Traceback (most recent call last): File """" usr lib python2.7 site-packages nova compute manager.py"""", line 6752, in update_available_resource_for_node rt.update_available_resource(context, nodename) File """" usr lib python2.7 site-packages nova compute resource_tracker.py"""", line 384, in update_available_resource self._update_available_resource(context, resources) File """" usr lib python2.7 site-packages oslo_concurrency lockutils.py"""", line 271, in inner return f(*args, **kwargs) File """" usr lib python2.7 site-packages nova compute resource_tracker.py"""", line 405, in _update_available_resource self._pair_instances_to_migrations(instances) TypeError: _pair_instances_to_migrations() takes exactly 3 arguments (2 given) None""",11
61a879b0,"""Error updating resources for node localhost.localdomain.: TypeError: _update_usage_from_instances() takes exactly 4 arguments (3 given) Traceback (most recent call last): File """" usr lib python2.7 site-packages nova compute manager.py"""", line 6752, in update_available_resource_for_node rt.update_available_resource(context, nodename) File """" usr lib python2.7 site-packages nova compute resource_tracker.py"""", line 384, in update_available_resource self._update_available_resource(context, resources) File """" usr lib python2.7 site-packages oslo_concurrency lockutils.py"""", line 271, in inner return f(*args, **kwargs) File """" usr lib python2.7 site-packages nova compute resource_tracker.py"""", line 403, in _update_available_resource self._update_usage_from_instances(instances, nodename) TypeError: _update_usage_from_instances() takes exactly 4 arguments (3 given) None""",11
6065c610,. None,4
af901f3b,", key) KeyTypeError: Key None must be of type basestring not NoneType None",8
aa213323,<class 'oslo_versionedobjects.fields.KeyTypeError'> (HTTP 500) (Request-ID: req-48fe2abf-0b4c-43ff-9c86-23b5617ab5e4),1
5cf8143d,"""Exception during message handling: AttributeError: 'NoneType' object has no attribute 'get' Traceback (most recent call last): File """" usr lib python2.7 site-packages oslo_messaging rpc server.py"""", line 160, in _process_incoming res = self.dispatcher.dispatch(message) File """" usr lib python2.7 site-packages oslo_messaging rpc dispatcher.py"""", line 213, in dispatch return self._do_dispatch(endpoint, method, ctxt, args) File """" usr lib python2.7 site-packages oslo_messaging rpc dispatcher.py"""", line 183, in _do_dispatch result = func(ctxt, **new_args) File """" usr lib python2.7 site-packages nova consoleauth manager.py"""", line 185, in delete_tokens_for_instance tokens = self._get_tokens_for_instance(instance_uuid) File """" usr lib python2.7 site-packages nova consoleauth manager.py"""", line 146, in _get_tokens_for_instance tokens_str = self.mc_instance.get(instance_uuid.encode('UTF-8')) AttributeError: 'NoneType' object has no attribute 'get' None""",1
deb063d6,) TypeError: 'NoneType' object is not iterable None,2
1b21026f,Traceback (most recent call last):,43
d93a62c2,Il server di metadati remoto ha rilevato un errore di server interno.,143
cfc6130c,Unlink failed for dev disk by-id <*>,3
64637844,"Periodic task is updating the host stats; it is trying to get disk info for instance-00000004, but the backing disk was removed by a concurrent operation (task_state=deleting)",1
c3c0e619,""", e, sys.exc_info()) File """" usr lib python2.7 site-packages oslo_utils excutils.py"""", line 220, in __exit__ self.force_reraise() File """" usr lib python2.7 site-packages oslo_utils excutils.py"""", line 196, in force_reraise six.reraise(self.type_, self.value, self.tb) File """" usr lib python2.7 site-packages nova compute manager.py"""", line 172, in decorated_function return function(self, context, *args, **kwargs) File """" usr lib python2.7 site-packages nova compute manager.py"""", line 1454, in terminate_instance do_terminate_instance(instance, bdms) File """" usr lib python2.7 site-packages oslo_concurrency lockutils.py"""", line 271, in inner return f(*args, **kwargs) File """" usr lib python2.7 site-packages nova compute manager.py"""", line 1453, in do_terminate_instance self._set_instance_obj_error_state(context, instance) File """" usr lib python2.7 site-packages oslo_utils excutils.py"""", line 220, in __exit__ self.force_reraise() File """" usr lib python2.7 site-packages oslo_utils excutils.py"""", line 196, in force_reraise six.reraise(self.type_, self.value, self.tb) File """" usr lib python2.7 site-packages nova compute manager.py"""", line 1447, in do_terminate_instance self._delete_instance(context, instance, bdms) File """" usr lib python2.7 site-packages nova hooks.py"""", line 154, in inner rv = f(*args, **kwargs) File """" usr lib python2.7 site-packages nova compute manager.py"""", line 1430, in _delete_instance self._complete_deletion(context, instance, bdms, system_meta) File """" usr lib python2.7 site-packages nova compute manager.py"""", line 507, in _complete_deletion compute_utils.notify_about_instance_action(instance, self.host, action=fields.NotificationAction.DELETE, phase=fields.NotificationPhase.END) File """" usr lib python2.7 site-packages nova rpc.py"""", line 225, in wrapped return f(*args, **kwargs) TypeError: notify_about_instance_action() takes at least 4 arguments (4 given) None""",1
4513d553,No ports have port_id starting with <*>,7
e666ec6f,Failed to get metadata for instance id: <*>,73
bac0f26e,Failed to deallocate network for instance. Error: 'NoneType' object is not iterable,1
4af2a496,TypeError: 'NoneType' object is not iterable None,25
d1fcc31d,Original exception being dropped:,1
6899ef8a,"Could not clean up failed build, not rescheduling. Error: 'NoneType' object is not iterable",1
2b548192,api_servers with fully qualified url including scheme (http https): BuildAbortException: La build dell'istanza 071f01a3-1f27-4a26-aaec-b12423ffa7aa \xe8 stata interrotta: 'NoneType' object is not iterable,1
d6d9af41,"""Unexpected exception in API method: TypeError: 'NoneType' object is not iterable Traceback (most recent call last): File """" usr lib python2.7 site-packages nova api openstack extensions.py"""", line 336, in wrapped return f(*args, **kwargs) File """" usr lib python2.7 site-packages nova api openstack compute servers.py"""", line 442, in show return self._view_builder.show(req, instance) File """" usr lib python2.7 site-packages nova api openstack compute views servers.py"""", line 145, in show extend_address), File """" usr lib python2.7 site-packages nova api openstack compute views servers.py"""", line 252, in _get_addresses networks = common.get_networks_for_instance(context, instance) File """" usr lib python2.7 site-packages nova api openstack common.py"""", line 326, in get_networks_for_instance return get_networks_for_instance_from_nw_info(nw_info) File """" usr lib python2.7 site-packages nova api openstack common.py"""", line 293, in get_networks_for_instance_from_nw_info for vif in nw_info: TypeError: 'NoneType' object is not iterable None""",5
b8e9463c,"""File """" usr lib python2.7 site-packages nova api openstack compute views servers.py"""", line 145, in show extend_address), File """" usr lib python2.7 site-packages nova api openstack compute views servers.py"""", line 252, in _get_addresses networks = common.get_networks_for_instance(context, instance) File """" usr lib python2.7 site-packages nova api openstack common.py"""", line 326, in get_networks_for_instance return get_networks_for_instance_from_nw_info(nw_info) File """" usr lib python2.7 site-packages nova api openstack common.py"""", line 293, in get_networks_for_instance_from_nw_info for vif in nw_info: TypeError: 'NoneType' object is not iterable None""",8
699ceb91,KeyError: u'6c2b2c2d-2c04-4eb0-b488-e041b8ab0984' None,1
f7b46d4a,10.0.20.24:8774 v2.1 e80c8f8d9a994fdcb38348700180bb81 servers detail?all_tenants=True&changes-since=2018-07-03T11%3A24%3A16.237779%2B00%3A00 returned with HTTP 500,1
ebc210ae,""", req, id) File """" usr lib python2.7 site-packages nova api openstack compute servers.py"""", line 685, in _delete self.compute_api.delete(context, instance) File """" usr lib python2.7 site-packages nova compute api.py"""", line 161, in inner return function(self, context, instance, *args, **kwargs) File """" usr lib python2.7 site-packages nova compute api.py"""", line 169, in _wrapped return fn(self, context, instance, *args, **kwargs) File """" usr lib python2.7 site-packages nova compute api.py"""", line 121, in inner return f(self, context, instance, *args, **kw) File """" usr lib python2.7 site-packages nova compute api.py"""", line 1167, in delete self._delete_instance(instance) TypeError: _delete_instance() takes exactly 3 arguments (2 given) None""",1
671ad216,"""Impossibile associare l'IP mobile 172.24.4.8 all'IP fisso 11.35.1.4 per l'istanza a54e4153-e696-4def-ab5b-3114b445cffe. Errore: : Exception Traceback (most recent call last): File """" usr lib python2.7 site-packages nova api openstack compute floating_ips.py"""", line 267, in _add_floating_ip fixed_address=fixed_address) File """" usr lib python2.7 site-packages nova network base_api.py"""", line 79, in wrapper raise Exception Exception None""",1
287da782,HTTP exception thrown: Impossibile associare l'IP mobile 172.24.4.8 all'IP fisso 11.35.1.4 per l'istanza a54e4153-e696-4def-ab5b-3114b445cffe. Errore:,1
47615a2f,Impossibile associare l'IP mobile 172.24.4.8 all'IP fisso 11.35.1.4 per l'istanza a54e4153-e696-4def-ab5b-3114b445cffe. Errore: (HTTP 400) (Request-ID: req-b9b6c1d0-9620-46ae-b734-e2aefae3be28),1
c26b2407,Failed to deallocate network for instance. Error: : Exception,3
a831b9ce,""", e, sys.exc_info()) File """" usr lib python2.7 site-packages oslo_utils excutils.py"""", line 220, in __exit__ self.force_reraise() File """" usr lib python2.7 site-packages oslo_utils excutils.py"""", line 196, in force_reraise six.reraise(self.type_, self.value, self.tb) File """" usr lib python2.7 site-packages nova compute manager.py"""", line 206, in decorated_function return function(self, context, *args, **kwargs) File """" usr lib python2.7 site-packages nova compute manager.py"""", line 2521, in terminate_instance do_terminate_instance(instance, bdms) File """" usr lib python2.7 site-packages oslo_concurrency lockutils.py"""", line 271, in inner return f(*args, **kwargs) File """" usr lib python2.7 site-packages nova compute manager.py"""", line 2519, in do_terminate_instance self._set_instance_obj_error_state(context, instance) File """" usr lib python2.7 site-packages oslo_utils excutils.py"""", line 220, in __exit__ self.force_reraise() File """" usr lib python2.7 site-packages oslo_utils excutils.py"""", line 196, in force_reraise six.reraise(self.type_, self.value, self.tb) File """" usr lib python2.7 site-packages nova compute manager.py"""", line 2509, in do_terminate_instance self._delete_instance(context, instance, bdms) File """" usr lib python2.7 site-packages nova hooks.py"""", line 154, in inner rv = f(*args, **kwargs) File """" usr lib python2.7 site-packages nova compute manager.py"""", line 2438, in _delete_instance self._shutdown_instance(context, instance, bdms) File """" usr lib python2.7 site-packages nova compute manager.py"""", line 2333, in _shutdown_instance self._try_deallocate_network(context, instance, requested_networks) File """" usr lib python2.7 site-packages nova compute manager.py"""", line 2255, in _try_deallocate_network self._set_instance_obj_error_state(context, instance) File """" usr lib python2.7 site-packages oslo_utils excutils.py"""", line 220, in __exit__ self.force_reraise() File """" usr lib python2.7 site-packages oslo_utils excutils.py"""", line 196, in force_reraise six.reraise(self.type_, self.value, self.tb) File """" usr lib python2.7 site-packages nova compute manager.py"""", line 2250, in _try_deallocate_network self._deallocate_network(context, instance, requested_networks) File """" usr lib python2.7 site-packages nova compute manager.py"""", line 1681, in _deallocate_network context, instance, requested_networks=requested_networks) File """" usr lib python2.7 site-packages nova network neutronv2 api.py"""", line <*> in deallocate_for_instance raise Exception Exception None""",2
b5d66d95,"""Unexpected exception in API method: Exception Traceback (most recent call last): File """" usr lib python2.7 site-packages nova api openstack extensions.py"""", line 336, in wrapped return f(*args, **kwargs) File """" usr lib python2.7 site-packages nova api validation __init__.py"""", line 181, in wrapper return func(*args, **kwargs) File """" usr lib python2.7 site-packages nova api validation __init__.py"""", line 181, in wrapper return func(*args, **kwargs) File """" usr lib python2.7 site-packages nova api openstack compute servers.py"""", line <*> in <*> servers = self._get_servers(req, <*> File """" usr lib python2.7 site-packages nova api openstack compute servers.py"""", line 220, in _get_servers raise Exception Exception None""",8
9193527c,<type 'exceptions.Exception'> (HTTP 500) (Request-ID: req-e65f3bb5-282d-4bb0-bae2-5e8263e407b1),1
d70b9e96,: Exception,1
e599e359,api_servers with fully qualified url including scheme (http https): <*>,3
95e880a1,"Could not clean up failed build, not rescheduling. Error: : Exception",1
bea1ad5c,api_servers with fully qualified url including scheme (http https): BuildAbortException: La build dell'istanza 39a10337-b547-4a12-88b8-73e39139d7ac \xe8 stata interrotta:,1
2bb55381,Failed to revert task state for instance. Error:,2
4cace397,"""Exception during message handling: Exception Traceback (most recent call last): File """" usr lib python2.7 site-packages oslo_messaging rpc server.py"""", line 160, in _process_incoming res = self.dispatcher.dispatch(message) File """" usr lib python2.7 site-packages oslo_messaging rpc dispatcher.py"""", line 213, in dispatch return self._do_dispatch(endpoint, method, ctxt, args) File """" usr lib python2.7 site-packages oslo_messaging rpc dispatcher.py"""", line 183, in _do_dispatch result = func(ctxt, **new_args) File """" usr lib python2.7 site-packages nova conductor manager.py"""", line 1125, in schedule_and_build_instances instance.create() File """" usr lib python2.7 site-packages oslo_versionedobjects base.py"""", line 226, in wrapper return fn(self, *args, **kwargs) File """" usr lib python2.7 site-packages nova objects instance.py"""", line 554, in create db_inst = db.instance_create(self._context, updates) File """" usr lib python2.7 site-packages nova db api.py"""", line 734, in instance_create return IMPL.instance_create(context, values) File """" usr lib python2.7 site-packages nova db sqlalchemy api.py"""", line 135, in wrapper return f(*args, **kwargs) File """" usr lib python2.7 site-packages oslo_db api.py"""", line 150, in wrapper ectxt.value = e.inner_exc File """" usr lib python2.7 site-packages oslo_utils excutils.py"""", line 220, in __exit__ self.force_reraise() File """" usr lib python2.7 site-packages oslo_utils excutils.py"""", line 196, in force_reraise six.reraise(self.type_, self.value, self.tb) File """" usr lib python2.7 site-packages oslo_db api.py"""", line 138, in wrapper return f(*args, **kwargs) File """" usr lib python2.7 site-packages nova db sqlalchemy api.py"""", line 180, in wrapped return f(context, *args, **kwargs) File """" usr lib python2.7 site-packages nova db sqlalchemy api.py"""", line 1103, in instance_create raise Exception Exception None""",1
4d89da7e,"""Exception during message handling: Exception Traceback (most recent call last): File """" usr lib python2.7 site-packages oslo_messaging rpc server.py"""", line 160, in _process_incoming res = self.dispatcher.dispatch(message) File """" usr lib python2.7 site-packages oslo_messaging rpc dispatcher.py"""", line 213, in dispatch return self._do_dispatch(endpoint, method, ctxt, args) File """" usr lib python2.7 site-packages oslo_messaging rpc dispatcher.py"""", line 183, in _do_dispatch result = func(ctxt, **new_args) File """" usr lib python2.7 site-packages nova conductor manager.py"""", line <*> in schedule_and_build_instances raise Exception Exception None""",3
42c593ba,"Could not clean up failed build, not rescheduling. Error: unsupported operand type(s) for +: 'NoneType' and 'str'",1
eb99df1b,api_servers with fully qualified url including scheme (http https): BuildAbortException: La build dell'istanza <*> \xe8 stata interrotta: 'NoneType' object has no attribute <*>,3
c2b3b398,""", e, sys.exc_info()) File """" usr lib python2.7 site-packages oslo_utils excutils.py"""", line 220, in __exit__ self.force_reraise() File """" usr lib python2.7 site-packages oslo_utils excutils.py"""", line 196, in force_reraise six.reraise(self.type_, self.value, self.tb) File """" usr lib python2.7 site-packages nova compute manager.py"""", line 172, in decorated_function return function(self, context, *args, **kwargs) File """" usr lib python2.7 site-packages nova compute manager.py"""", line 1454, in terminate_instance do_terminate_instance(instance, bdms) File """" usr lib python2.7 site-packages oslo_concurrency lockutils.py"""", line 271, in inner return f(*args, **kwargs) File """" usr lib python2.7 site-packages nova compute manager.py"""", line 1453, in do_terminate_instance self._set_instance_obj_error_state(context, instance) File """" usr lib python2.7 site-packages oslo_utils excutils.py"""", line 220, in __exit__ self.force_reraise() File """" usr lib python2.7 site-packages oslo_utils excutils.py"""", line 196, in force_reraise six.reraise(self.type_, self.value, self.tb) File """" usr lib python2.7 site-packages nova compute manager.py"""", line 1447, in do_terminate_instance self._delete_instance(context, instance, bdms) File """" usr lib python2.7 site-packages nova hooks.py"""", line 154, in inner rv = f(*args, **kwargs) File """" usr lib python2.7 site-packages nova compute manager.py"""", line 1430, in _delete_instance self._complete_deletion(context, instance, bdms, system_meta) File """" usr lib python2.7 site-packages nova compute manager.py"""", line <*> in _complete_deletion raise Exception Exception None""",2
a8113918,"Exception dispatching event <LifecycleEvent: 1530324228.11, c99768f8-cd4d-4ac2-985f-11c1b86bdddc => In pausa>: : Exception",1
070cd33e,Exception dispatching event <LifecycleEvent: <*> c99768f8-cd4d-4ac2-985f-11c1b86bdddc => <*> : Exception,4
c62ff7e7,""", e, sys.exc_info()) File """" usr lib python2.7 site-packages oslo_utils excutils.py"""", line 220, in __exit__ self.force_reraise() File """" usr lib python2.7 site-packages oslo_utils excutils.py"""", line 196, in force_reraise six.reraise(self.type_, self.value, self.tb) File """" usr lib python2.7 site-packages nova compute manager.py"""", line 172, in decorated_function return function(self, context, *args, **kwargs) File """" usr lib python2.7 site-packages nova compute manager.py"""", line 1454, in terminate_instance do_terminate_instance(instance, bdms) File """" usr lib python2.7 site-packages oslo_concurrency lockutils.py"""", line 271, in inner return f(*args, **kwargs) File """" usr lib python2.7 site-packages nova compute manager.py"""", line 1453, in do_terminate_instance self._set_instance_obj_error_state(context, instance) File """" usr lib python2.7 site-packages oslo_utils excutils.py"""", line 220, in __exit__ self.force_reraise() File """" usr lib python2.7 site-packages oslo_utils excutils.py"""", line 196, in force_reraise six.reraise(self.type_, self.value, self.tb) File """" usr lib python2.7 site-packages nova compute manager.py"""", line 1447, in do_terminate_instance self._delete_instance(context, instance, bdms) File """" usr lib python2.7 site-packages nova hooks.py"""", line 154, in inner rv = f(*args, **kwargs) File """" usr lib python2.7 site-packages nova compute manager.py"""", line 1414, in _delete_instance raise Exception Exception None""",1
34c01a4c,Port <*> was not found on the integration bridge and will therefore not be processed,3
7afd3fd5,") skipped, changing status to down",3
f28720ba,Cannot reboot instance: Unexpected error while running command.,1
b76bada8,""", e, sys.exc_info()) File """" usr lib python2.7 site-packages oslo_utils excutils.py"""", line 220, in __exit__ self.force_reraise() File """" usr lib python2.7 site-packages oslo_utils excutils.py"""", line 196, in force_reraise six.reraise(self.type_, self.value, self.tb) File """" usr lib python2.7 site-packages nova compute manager.py"""", line 206, in decorated_function return function(self, context, *args, **kwargs) File """" usr lib python2.7 site-packages nova compute manager.py"""", line 3149, in reboot_instance self._set_instance_obj_error_state(context, instance) File """" usr lib python2.7 site-packages oslo_utils excutils.py"""", line 220, in __exit__ self.force_reraise() File """" usr lib python2.7 site-packages oslo_utils excutils.py"""", line 196, in force_reraise six.reraise(self.type_, self.value, self.tb) File """" usr lib python2.7 site-packages nova compute manager.py"""", line 3124, in reboot_instance bad_volumes_callback=bad_volumes_callback) File """" usr lib python2.7 site-packages nova virt libvirt driver.py"""", line 2506, in reboot block_device_info) File """" usr lib python2.7 site-packages nova virt libvirt driver.py"""", line 2606, in _hard_reboot backing_disk_info) File """" usr lib python2.7 site-packages nova virt libvirt driver.py"""", line 7231, in _create_images_and_backing fallback_from_host) File """" usr lib python2.7 site-packages nova virt libvirt driver.py"""", line 7145, in _try_fetch_image_cache size=size) File """" usr lib python2.7 site-packages nova virt libvirt imagebackend.py"""", line 247, in cache self.resize_image(size) File """" usr lib python2.7 site-packages nova virt libvirt imagebackend.py"""", line 634, in resize_image disk.extend(image, size) File """" usr lib python2.7 site-packages nova virt disk api.py"""", line 190, in extend utils.execute('qemu-img', 'resize', image.path, size) File """" usr lib python2.7 site-packages nova utils.py"""", line 288, in execute return processutils.execute(*cmd, **kwargs) File """" usr lib python2.7 site-packages oslo_concurrency processutils.py"""", line 419, in execute cmd=sanitized_cmd) ProcessExecutionError: Unexpected error while running command. Command: qemu-img resize var lib nova instances d72831be-d139-4ee8-b3af-08db8a5332a9 disk 1073741824 Exit code: 1 Stdout: u'' Stderr: u""""qemu-img: Could not open ' var lib nova instances d72831be-d139-4ee8-b3af-08db8a5332a9 disk': Could not open ' var lib nova instances d72831be-d139-4ee8-b3af-08db8a5332a9 disk': Permission denied\n"""" None""",1
7981fd0c,) TypeError: 'NoneType' object has no attribute '__getitem__' None,2
ef6e7b9e,"""Failed to get metadata for instance id: <*> AttributeError: 'NoneType' object has no attribute 'id' Traceback (most recent call last): File """" usr lib python2.7 site-packages nova api metadata handler.py"""", line 285, in _get_meta_by_instance_id remote_address) File """" usr lib python2.7 site-packages nova api metadata handler.py"""", line 82, in get_metadata_by_instance_id data = base.get_metadata_by_instance_id(instance_id, address) File """" usr lib python2.7 site-packages nova api metadata base.py"""", line 708, in get_metadata_by_instance_id expected_attrs=attrs) File """" usr lib python2.7 site-packages oslo_versionedobjects base.py"""", line 184, in wrapper result = fn(cls, context, *args, **kwargs) File """" usr lib python2.7 site-packages nova objects instance.py"""", line 469, in get_by_uuid expected_attrs) File """" usr lib python2.7 site-packages nova objects instance.py"""", line 397, in _from_db_object instance._load_ec2_ids() File """" usr lib python2.7 site-packages nova objects instance.py"""", line 918, in _load_ec2_ids self.ec2_ids = objects.EC2Ids.get_by_instance(self._context, self) File """" usr lib python2.7 site-packages oslo_versionedobjects base.py"""", line 184, in wrapper result = fn(cls, context, *args, **kwargs) File """" usr lib python2.7 site-packages nova objects ec2.py"""", line 216, in get_by_instance ec2_ids = cls._get_ec2_ids(context, instance) File """" usr lib python2.7 site-packages nova objects ec2.py"""", line 202, in _get_ec2_ids instance.image_ref) File """" usr lib python2.7 site-packages nova api ec2 ec2utils.py"""", line 127, in glance_id_to_ec2_id image_id = glance_id_to_id(context, glance_id) File """" usr lib python2.7 site-packages nova api ec2 ec2utils.py"""", line 49, in memoizer value = func(context, reqid) File """" usr lib python2.7 site-packages nova api ec2 ec2utils.py"""", line 114, in glance_id_to_id return objects.S3ImageMapping.get_by_uuid(context, glance_id).id AttributeError: 'NoneType' object has no attribute 'id' None""",80
c9bad235,"""Traceback (most recent call last): File """" usr lib64 python2.7 site-packages libvirt.py"""", line 4747, in _dispatchDomainEventLifecycleCallback cb(self, virDomain(self, _obj=dom), event, detail, opaque) File """" usr lib python2.7 site-packages nova virt libvirt host.py"""", line 125, in _event_lifecycle_callback self._queue_event(virtevent.LifecycleEvent(uuid, transition)) File """" usr lib python2.7 site-packages nova virt libvirt host.py"""", line 164, in _queue_event raise IOError IOError None""",8
74f65208,Unhandled error: IOError,8
4c3c3b56,Unhandled error: TypeError: write() takes exactly 2 arguments (1 given),8
aa4fad83,"""Traceback (most recent call last): File """" usr lib64 python2.7 site-packages libvirt.py"""", line 4747, in _dispatchDomainEventLifecycleCallback cb(self, virDomain(self, _obj=dom), event, detail, opaque) File """" usr lib python2.7 site-packages nova virt libvirt host.py"""", line 125, in _event_lifecycle_callback self._queue_event(virtevent.LifecycleEvent(uuid, transition)) File """" usr lib python2.7 site-packages nova virt libvirt host.py"""", line 164, in _queue_event self._event_notify_send.write() TypeError: write() takes exactly 2 arguments (1 given) None""",8
808039a9,api_servers with fully qualified url including scheme (http https): ImageUnacceptable: L'immagine 6329a697-754f-48f3-abac-86c9e1886196 non \xe8 accettabile: Impossibile convertire l'immagine in immagine non elaborata: L'immagine None non \xe8 accettabile: Impossibile convertire l'immagine in raw: Unexpected error while running command.,3
4942406d,""", e, sys.exc_info()) File """" usr lib python2.7 site-packages oslo_utils excutils.py"""", line 220, in __exit__ self.force_reraise() File """" usr lib python2.7 site-packages oslo_utils excutils.py"""", line 196, in force_reraise six.reraise(self.type_, self.value, self.tb) File """" usr lib python2.7 site-packages nova compute manager.py"""", line 206, in decorated_function return function(self, context, *args, **kwargs) File """" usr lib python2.7 site-packages nova compute manager.py"""", line 3149, in reboot_instance self._set_instance_obj_error_state(context, instance) File """" usr lib python2.7 site-packages oslo_utils excutils.py"""", line 220, in __exit__ self.force_reraise() File """" usr lib python2.7 site-packages oslo_utils excutils.py"""", line 196, in force_reraise six.reraise(self.type_, self.value, self.tb) File """" usr lib python2.7 site-packages nova compute manager.py"""", line 3124, in reboot_instance bad_volumes_callback=bad_volumes_callback) File """" usr lib python2.7 site-packages nova virt libvirt driver.py"""", line 1396, in reboot return self._hard_reboot(context, instance, network_info, block_device_info) File """" usr lib python2.7 site-packages nova virt libvirt driver.py"""", line 1437, in _hard_reboot raise Exception Exception None""",1
26932d58,""", e, sys.exc_info()) File """" usr lib python2.7 site-packages oslo_utils excutils.py"""", line 220, in __exit__ self.force_reraise() File """" usr lib python2.7 site-packages oslo_utils excutils.py"""", line 196, in force_reraise six.reraise(self.type_, self.value, self.tb) File """" usr lib python2.7 site-packages nova compute manager.py"""", line 172, in decorated_function return function(self, context, *args, **kwargs) File """" usr lib python2.7 site-packages nova compute manager.py"""", line 1454, in terminate_instance do_terminate_instance(instance, bdms) File """" usr lib python2.7 site-packages oslo_concurrency lockutils.py"""", line 271, in inner return f(*args, **kwargs) File """" usr lib python2.7 site-packages nova compute manager.py"""", line 1453, in do_terminate_instance self._set_instance_obj_error_state(context, instance) File """" usr lib python2.7 site-packages oslo_utils excutils.py"""", line 220, in __exit__ self.force_reraise() File """" usr lib python2.7 site-packages oslo_utils excutils.py"""", line 196, in force_reraise six.reraise(self.type_, self.value, self.tb) File """" usr lib python2.7 site-packages nova compute manager.py"""", line 1447, in do_terminate_instance self._delete_instance(context, instance, bdms) File """" usr lib python2.7 site-packages nova hooks.py"""", line 154, in inner rv = f(*args, **kwargs) File """" usr lib python2.7 site-packages nova compute manager.py"""", line 1417, in _delete_instance self._shutdown_instance(context, instance, bdms) File """" usr lib python2.7 site-packages nova compute manager.py"""", line 1360, in _shutdown_instance self._try_deallocate_network(context, instance, requested_networks) File """" usr lib python2.7 site-packages nova compute manager.py"""", line 1319, in _try_deallocate_network self._set_instance_obj_error_state(context, instance) File """" usr lib python2.7 site-packages oslo_utils excutils.py"""", line 220, in __exit__ self.force_reraise() File """" usr lib python2.7 site-packages oslo_utils excutils.py"""", line 196, in force_reraise six.reraise(self.type_, self.value, self.tb) File """" usr lib python2.7 site-packages nova compute manager.py"""", line 1313, in _try_deallocate_network raise Exception Exception None""",1
aff87fe0,""", e, sys.exc_info()) File """" usr lib python2.7 site-packages oslo_utils excutils.py"""", line 220, in __exit__ self.force_reraise() File """" usr lib python2.7 site-packages oslo_utils excutils.py"""", line 196, in force_reraise six.reraise(self.type_, self.value, self.tb) File """" usr lib python2.7 site-packages nova compute manager.py"""", line 172, in decorated_function return function(self, context, *args, **kwargs) File """" usr lib python2.7 site-packages nova compute manager.py"""", line 1454, in terminate_instance do_terminate_instance(instance, bdms) File """" usr lib python2.7 site-packages oslo_concurrency lockutils.py"""", line 271, in inner return f(*args, **kwargs) File """" usr lib python2.7 site-packages nova compute manager.py"""", line 1453, in do_terminate_instance self._set_instance_obj_error_state(context, instance) File """" usr lib python2.7 site-packages oslo_utils excutils.py"""", line 220, in __exit__ self.force_reraise() File """" usr lib python2.7 site-packages oslo_utils excutils.py"""", line 196, in force_reraise six.reraise(self.type_, self.value, self.tb) File """" usr lib python2.7 site-packages nova compute manager.py"""", line 1447, in do_terminate_instance self._delete_instance(context, instance, bdms) File """" usr lib python2.7 site-packages nova hooks.py"""", line 154, in inner rv = f(*args, **kwargs) File """" usr lib python2.7 site-packages nova compute manager.py"""", line 1417, in _delete_instance self._shutdown_instance(context, instance, bdms) File """" usr lib python2.7 site-packages nova compute manager.py"""", line 1358, in _shutdown_instance raise Exception Exception None""",1
ee7f1b31,""", encryption=encryption) File """" usr lib python2.7 site-packages nova virt libvirt driver.py"""", line 1302, in attach_volume self._disconnect_volume(connection_info, disk_dev, instance) File """" usr lib python2.7 site-packages oslo_utils excutils.py"""", line 220, in __exit__ self.force_reraise() File """" usr lib python2.7 site-packages oslo_utils excutils.py"""", line 196, in force_reraise six.reraise(self.type_, self.value, self.tb) File """" usr lib python2.7 site-packages nova virt libvirt driver.py"""", line 1296, in attach_volume context, instance) File """" usr lib python2.7 site-packages nova virt libvirt driver.py"""", line 8064, in _build_device_metadata instance.uuid) File """" usr lib python2.7 site-packages oslo_versionedobjects base.py"""", line 177, in wrapper args, kwargs) File """" usr lib python2.7 site-packages nova conductor rpcapi.py"""", line 240, in object_class_action_versions args=args, kwargs=kwargs) File """" usr lib python2.7 site-packages oslo_messaging rpc client.py"""", line 116, in call msg_ctxt = self.serializer.serialize_context(ctxt) File """" usr lib python2.7 site-packages nova rpc.py"""", line 147, in serialize_context self).serialize_context(context) File """" usr lib python2.7 site-packages nova rpc.py"""", line 138, in serialize_context return context.to_dict() AttributeError: 'NoneType' object has no attribute 'to_dict' None""",1
a58526ac,"Periodic task is updating the host stats, it is trying to get disk info for instance-00000004, but the backing volume block device was removed by concurrent operations such as resize. Error: Nessuna associazione dell'unitÃ di blocco del volume nel percorso: dev sdb: VolumeBDMPathNotFound: Nessuna associazione dell'unit\xe0 di blocco del volume nel percorso: dev sdb",1
9a35f684,Cannot reboot instance: <*>,3
2b3681ad,) KeyError: 'data' None,1
92dbdc40,", KeyError: 'target_portal' None",1
e00d67e7,"The support for the Cinder API v2 is deprecated, please upgrade to Cinder API v3.: VolumeDriverNotFound: Impossibile trovare un gestore per il volume None.",2
7c3e51b9,""", encryption=encryption) File """" usr lib python2.7 site-packages nova virt libvirt driver.py"""", line 811, in attach_volume conf = self._get_volume_config(connection_info, disk_info) File """" usr lib python2.7 site-packages nova virt libvirt driver.py"""", line 773, in _get_volume_config vol_driver = self._get_volume_driver(connection_info) File """" usr lib python2.7 site-packages nova virt libvirt driver.py"""", line 753, in _get_volume_driver raise exception.VolumeDriverNotFound(driver_type=driver_type) VolumeDriverNotFound: Impossibile trovare un gestore per il volume None. None""",1
9483c621,"""Fixed interval looping call <*> failed: InstanceNotFound: Impossibile trovare l'istanza <*> Traceback (most recent call last): File """" usr lib python2.7 site-packages oslo_service loopingcall.py"""", line 137, in _run_loop result = func(*self.args, **self.kw) File """" usr lib python2.7 site-packages nova virt libvirt driver.py"""", line <*> in <*> state = self.get_info(instance).state File """" usr lib python2.7 site-packages nova virt libvirt driver.py"""", line 2959, in get_info guest = self._host.get_guest(instance) File """" usr lib python2.7 site-packages nova virt libvirt host.py"""", line 534, in get_guest return libvirt_guest.Guest(self.get_domain(instance)) File """" usr lib python2.7 site-packages nova virt libvirt host.py"""", line 555, in get_domain raise exception.InstanceNotFound(instance_id=instance.uuid) InstanceNotFound: Impossibile trovare l'istanza <*> None""",2
29edf214,api_servers with fully qualified url including scheme (http https): InstanceNotFound: Impossibile trovare l'istanza bc35d58b-8b92-4d28-adf4-03a35882f23e.,3
3327ffcf,Cannot reboot instance: Impossibile trovare l'istanza d78c2881-b86a-4261-9074-ce2ab5f6d5a2.: InstanceNotFound: Impossibile trovare l'istanza d78c2881-b86a-4261-9074-ce2ab5f6d5a2.,1
b586d301,"""Exception during message handling: InstanceNotFound: Impossibile trovare l'istanza d78c2881-b86a-4261-9074-ce2ab5f6d5a2. Traceback (most recent call last): File """" usr lib python2.7 site-packages oslo_messaging rpc server.py"""", line 160, in _process_incoming res = self.dispatcher.dispatch(message) File """" usr lib python2.7 site-packages oslo_messaging rpc dispatcher.py"""", line 213, in dispatch return self._do_dispatch(endpoint, method, ctxt, args) File """" usr lib python2.7 site-packages oslo_messaging rpc dispatcher.py"""", line 183, in _do_dispatch result = func(ctxt, **new_args) File """" usr lib python2.7 site-packages nova exception_wrapper.py"""", line 76, in wrapped function_name, call_dict, binary) File """" usr lib python2.7 site-packages oslo_utils excutils.py"""", line 220, in __exit__ self.force_reraise() File """" usr lib python2.7 site-packages oslo_utils excutils.py"""", line 196, in force_reraise six.reraise(self.type_, self.value, self.tb) File """" usr lib python2.7 site-packages nova exception_wrapper.py"""", line 67, in wrapped return f(self, context, *args, **kw) File """" usr lib python2.7 site-packages nova compute manager.py"""", line 190, in decorated_function """"Error: %s"""", e, instance=instance) File """" usr lib python2.7 site-packages oslo_utils excutils.py"""", line 220, in __exit__ self.force_reraise() File """" usr lib python2.7 site-packages oslo_utils excutils.py"""", line 196, in force_reraise six.reraise(self.type_, self.value, self.tb) File """" usr lib python2.7 site-packages nova compute manager.py"""", line 160, in decorated_function return function(self, context, *args, **kwargs) File """" usr lib python2.7 site-packages nova compute utils.py"""", line 880, in decorated_function return function(self, context, *args, **kwargs) File """" usr lib python2.7 site-packages nova compute manager.py"""", line 206, in decorated_function return function(self, context, *args, **kwargs) File """" usr lib python2.7 site-packages nova compute manager.py"""", line 3149, in reboot_instance self._set_instance_obj_error_state(context, instance) File """" usr lib python2.7 site-packages oslo_utils excutils.py"""", line 220, in __exit__ self.force_reraise() File """" usr lib python2.7 site-packages oslo_utils excutils.py"""", line 196, in force_reraise six.reraise(self.type_, self.value, self.tb) File """" usr lib python2.7 site-packages nova compute manager.py"""", line 3124, in reboot_instance bad_volumes_callback=bad_volumes_callback) File """" usr lib python2.7 site-packages nova virt libvirt driver.py"""", line 1396, in reboot return self._hard_reboot(context, instance, network_info, block_device_info) File """" usr lib python2.7 site-packages nova virt libvirt driver.py"""", line 1449, in _hard_reboot timer.start(interval=0.5).wait() File """" usr lib python2.7 site-packages eventlet event.py"""", line 121, in wait return hubs.get_hub().switch() File """" usr lib python2.7 site-packages eventlet hubs hub.py"""", line 294, in switch return self.greenlet.switch() File """" usr lib python2.7 site-packages oslo_service loopingcall.py"""", line 137, in _run_loop result = func(*self.args, **self.kw) File """" usr lib python2.7 site-packages nova virt libvirt driver.py"""", line 1444, in _wait_for_reboot state = self.get_info(instance).state File """" usr lib python2.7 site-packages nova virt libvirt driver.py"""", line 2959, in get_info guest = self._host.get_guest(instance) File """" usr lib python2.7 site-packages nova virt libvirt host.py"""", line 534, in get_guest return libvirt_guest.Guest(self.get_domain(instance)) File """" usr lib python2.7 site-packages nova virt libvirt host.py"""", line 555, in get_domain raise exception.InstanceNotFound(instance_id=instance.uuid) InstanceNotFound: Impossibile trovare l'istanza d78c2881-b86a-4261-9074-ce2ab5f6d5a2. None""",1
f74207da,Cannot reboot instance: Impossibile trovare un gestore per il volume None.: VolumeDriverNotFound: Impossibile trovare un gestore per il volume None.,1
8b699885,""", e, sys.exc_info()) File """" usr lib python2.7 site-packages oslo_utils excutils.py"""", line 220, in __exit__ self.force_reraise() File """" usr lib python2.7 site-packages oslo_utils excutils.py"""", line 196, in force_reraise six.reraise(self.type_, self.value, self.tb) File """" usr lib python2.7 site-packages nova compute manager.py"""", line 206, in decorated_function return function(self, context, *args, **kwargs) File """" usr lib python2.7 site-packages nova compute manager.py"""", line 3149, in reboot_instance self._set_instance_obj_error_state(context, instance) File """" usr lib python2.7 site-packages oslo_utils excutils.py"""", line 220, in __exit__ self.force_reraise() File """" usr lib python2.7 site-packages oslo_utils excutils.py"""", line 196, in force_reraise six.reraise(self.type_, self.value, self.tb) File """" usr lib python2.7 site-packages nova compute manager.py"""", line 3124, in reboot_instance bad_volumes_callback=bad_volumes_callback) File """" usr lib python2.7 site-packages nova virt libvirt driver.py"""", line 1467, in reboot return self._hard_reboot(context, instance, network_info, block_device_info) File """" usr lib python2.7 site-packages nova virt libvirt driver.py"""", line 1500, in _hard_reboot xml = self._get_guest_xml(context, instance, network_info, disk_info, instance.image_meta, block_device_info=block_device_info) File """" usr lib python2.7 site-packages nova virt libvirt driver.py"""", line 3019, in _get_guest_xml conf = self._get_guest_config(instance, network_info, image_meta, disk_info, rescue, block_device_info, context) File """" usr lib python2.7 site-packages nova virt libvirt driver.py"""", line 2909, in _get_guest_config storage_configs = self._get_guest_storage_config(instance, image_meta, disk_info, rescue, block_device_info, flavor, guest.os_type) File """" usr lib python2.7 site-packages nova virt libvirt driver.py"""", line 2221, in _get_guest_storage_config self._connect_volume(connection_info, info, instance) File """" usr lib python2.7 site-packages nova virt libvirt driver.py"""", line 757, in _connect_volume vol_driver = self._get_volume_driver(connection_info) File """" usr lib python2.7 site-packages nova virt libvirt driver.py"""", line 753, in _get_volume_driver raise exception.VolumeDriverNotFound(driver_type=driver_type) VolumeDriverNotFound: Impossibile trovare un gestore per il volume None. None""",1
ba88c7d8,"tcp:127.0.0.1:6640: no response to inactivity probe after <*> seconds, disconnecting",4
3d635119,", None) KeyError: 'data' None",1
dfb084e5,Failed to deallocate network for instance. Error: deallocate_for_instance() takes exactly 3 arguments (2 given),1
004cafb8,""", e, sys.exc_info()) File """" usr lib python2.7 site-packages oslo_utils excutils.py"""", line 220, in __exit__ self.force_reraise() File """" usr lib python2.7 site-packages oslo_utils excutils.py"""", line 196, in force_reraise six.reraise(self.type_, self.value, self.tb) File """" usr lib python2.7 site-packages nova compute manager.py"""", line 172, in decorated_function return function(self, context, *args, **kwargs) File """" usr lib python2.7 site-packages nova compute manager.py"""", line 1454, in terminate_instance do_terminate_instance(instance, bdms) File """" usr lib python2.7 site-packages oslo_concurrency lockutils.py"""", line 271, in inner return f(*args, **kwargs) File """" usr lib python2.7 site-packages nova compute manager.py"""", line 1453, in do_terminate_instance self._set_instance_obj_error_state(context, instance) File """" usr lib python2.7 site-packages oslo_utils excutils.py"""", line 220, in __exit__ self.force_reraise() File """" usr lib python2.7 site-packages oslo_utils excutils.py"""", line 196, in force_reraise six.reraise(self.type_, self.value, self.tb) File """" usr lib python2.7 site-packages nova compute manager.py"""", line 1447, in do_terminate_instance self._delete_instance(context, instance, bdms) File """" usr lib python2.7 site-packages nova hooks.py"""", line 154, in inner rv = f(*args, **kwargs) File """" usr lib python2.7 site-packages nova compute manager.py"""", line 1413, in _delete_instance self._notify_about_instance_usage(instance, 'delete.start') TypeError: _notify_about_instance_usage() takes at least 4 arguments (3 given) None""",1
c8b73b91,""", e, sys.exc_info()) File """" usr lib python2.7 site-packages oslo_utils excutils.py"""", line 220, in __exit__ self.force_reraise() File """" usr lib python2.7 site-packages oslo_utils excutils.py"""", line 196, in force_reraise six.reraise(self.type_, self.value, self.tb) File """" usr lib python2.7 site-packages nova compute manager.py"""", line 206, in decorated_function return function(self, context, *args, **kwargs) File """" usr lib python2.7 site-packages nova compute manager.py"""", line 3149, in reboot_instance self._set_instance_obj_error_state(context, instance) File """" usr lib python2.7 site-packages oslo_utils excutils.py"""", line 220, in __exit__ self.force_reraise() File """" usr lib python2.7 site-packages oslo_utils excutils.py"""", line 196, in force_reraise six.reraise(self.type_, self.value, self.tb) File """" usr lib python2.7 site-packages nova compute manager.py"""", line 3124, in reboot_instance bad_volumes_callback=bad_volumes_callback) File """" usr lib python2.7 site-packages nova virt libvirt driver.py"""", line 1400, in reboot return self._hard_reboot(context, instance, network_info, block_device_info) File """" usr lib python2.7 site-packages nova virt libvirt driver.py"""", line 1429, in _hard_reboot self.destroy(context, instance, network_info, destroy_disks=False, block_device_info=block_device_info) File """" usr lib python2.7 site-packages nova virt libvirt driver.py"""", line 510, in destroy self.cleanup(context, instance, network_info, block_device_info, destroy_disks) File """" usr lib python2.7 site-packages nova virt libvirt driver.py"""", line 580, in cleanup LOG.warning('Ignoring Volume Error on vol %(vol_id)s during delete %(exc)s', <*>'vol_id': vol.get('volume_id'), 'exc': exc}, instance=instance) File """" usr lib python2.7 site-packages oslo_utils excutils.py"""", line 220, in __exit__ self.force_reraise() File """" usr lib python2.7 site-packages oslo_utils excutils.py"""", line 196, in force_reraise six.reraise(self.type_, self.value, self.tb) File """" usr lib python2.7 site-packages nova virt libvirt driver.py"""", line 575, in cleanup self._disconnect_volume(connection_info, disk_dev, instance) File """" usr lib python2.7 site-packages nova virt libvirt driver.py"""", line 697, in _disconnect_volume vol_driver.disconnect_volume(disk_dev, instance) TypeError: disconnect_volume() takes exactly 4 arguments (3 given) None""",1
1289b10d,Ignoring Volume Error on vol None during delete <*> takes exactly 4 arguments (3 given),3
69901111,"Detach interface failed, port_id=e2fd0fef-8105-4840-b9c9-c32b2c3ad44c, reason: Impossibile trovare l'istanza 2015d6fd-e460-4dd5-a39b-3423f4d76fd8.",1
9605b7dd,"""Error updating resources for node localhost.localdomain.: DiskNotFound: Nessun disco in var lib nova instances 2015d6fd-e460-4dd5-a39b-3423f4d76fd8 disk Traceback (most recent call last): File """" usr lib python2.7 site-packages nova compute manager.py"""", line 3724, in update_available_resource_for_node rt.update_available_resource(context, nodename) File """" usr lib python2.7 site-packages nova compute resource_tracker.py"""", line 688, in update_available_resource resources = self.driver.get_available_resource(nodename) File """" usr lib python2.7 site-packages nova virt libvirt driver.py"""", line 5977, in get_available_resource disk_over_committed = self._get_disk_over_committed_size_total() File """" usr lib python2.7 site-packages nova virt libvirt driver.py"""", line 7538, in _get_disk_over_committed_size_total err_ctxt.reraise = False File """" usr lib python2.7 site-packages oslo_utils excutils.py"""", line 220, in __exit__ self.force_reraise() File """" usr lib python2.7 site-packages oslo_utils excutils.py"""", line 196, in force_reraise six.reraise(self.type_, self.value, self.tb) File """" usr lib python2.7 site-packages nova virt libvirt driver.py"""", line 7484, in _get_disk_over_committed_size_total config, block_device_info) File """" usr lib python2.7 site-packages nova virt libvirt driver.py"""", line 7383, in _get_instance_disk_info_from_config dk_size = disk_api.get_allocated_disk_size(path) File """" usr lib python2.7 site-packages nova virt disk api.py"""", line 156, in get_allocated_disk_size return images.qemu_img_info(path).disk_size File """" usr lib python2.7 site-packages nova virt images.py"""", line 57, in qemu_img_info raise exception.DiskNotFound(location=path) DiskNotFound: Nessun disco in var lib nova instances 2015d6fd-e460-4dd5-a39b-3423f4d76fd8 disk None""",10
8ecc3813,""", encryption=encryption) File """" usr lib python2.7 site-packages nova virt libvirt driver.py"""", line 739, in attach_volume self._connect_volume(disk_info, instance) TypeError: _connect_volume() takes exactly 4 arguments (3 given) None""",1
fdda0101,"""Error updating resources for node localhost.localdomain.: Exception Traceback (most recent call last): File """" usr lib python2.7 site-packages nova compute manager.py"""", line 6752, in update_available_resource_for_node rt.update_available_resource(context, nodename) File """" usr lib python2.7 site-packages nova compute resource_tracker.py"""", line 384, in update_available_resource self._update_available_resource(context, resources) File """" usr lib python2.7 site-packages oslo_concurrency lockutils.py"""", line 271, in inner return f(*args, **kwargs) File """" usr lib python2.7 site-packages nova compute resource_tracker.py"""", line 401, in _update_available_resource self._update_usage_from_instances(context, instances, nodename) File """" usr lib python2.7 site-packages nova compute resource_tracker.py"""", line <*> in _update_usage_from_instances raise Exception Exception None""",15
353b4929,"""Error updating resources for node localhost.localdomain.: Exception Traceback (most recent call last): File """" usr lib python2.7 site-packages nova compute manager.py"""", line 6752, in update_available_resource_for_node rt.update_available_resource(context, nodename) File """" usr lib python2.7 site-packages nova compute resource_tracker.py"""", line 384, in update_available_resource self._update_available_resource(context, resources) File """" usr lib python2.7 site-packages oslo_concurrency lockutils.py"""", line 271, in inner return f(*args, **kwargs) File """" usr lib python2.7 site-packages nova compute resource_tracker.py"""", line <*> in _update_available_resource raise Exception Exception None""",19
5a36a457,""", e, sys.exc_info()) File """" usr lib python2.7 site-packages oslo_utils excutils.py"""", line 220, in __exit__ self.force_reraise() File """" usr lib python2.7 site-packages oslo_utils excutils.py"""", line 196, in force_reraise six.reraise(self.type_, self.value, self.tb) File """" usr lib python2.7 site-packages nova compute manager.py"""", line 206, in decorated_function return function(self, context, *args, **kwargs) File """" usr lib python2.7 site-packages nova compute manager.py"""", line 3149, in reboot_instance self._set_instance_obj_error_state(context, instance) File """" usr lib python2.7 site-packages oslo_utils excutils.py"""", line 220, in __exit__ self.force_reraise() File """" usr lib python2.7 site-packages oslo_utils excutils.py"""", line 196, in force_reraise six.reraise(self.type_, self.value, self.tb) File """" usr lib python2.7 site-packages nova compute manager.py"""", line 3124, in reboot_instance bad_volumes_callback=bad_volumes_callback) File """" usr lib python2.7 site-packages nova virt libvirt driver.py"""", line 1396, in reboot return self._hard_reboot(context, instance, network_info, block_device_info) File """" usr lib python2.7 site-packages nova virt libvirt driver.py"""", line 1429, in _hard_reboot xml = self._get_guest_xml(context, instance, network_info, disk_info, instance.image_meta, block_device_info=block_device_info) File """" usr lib python2.7 site-packages nova virt libvirt driver.py"""", line 2952, in _get_guest_xml conf = self._get_guest_config(instance, network_info, image_meta, disk_info, rescue, block_device_info, context) File """" usr lib python2.7 site-packages nova virt libvirt driver.py"""", line 2842, in _get_guest_config storage_configs = self._get_guest_storage_config(instance, image_meta, disk_info, rescue, block_device_info, flavor, guest.os_type) File """" usr lib python2.7 site-packages nova virt libvirt driver.py"""", line 2152, in _get_guest_storage_config self._connect_volume(info, instance) TypeError: _connect_volume() takes exactly 4 arguments (3 given) None""",1
bd87e601,""", e, sys.exc_info()) File """" usr lib python2.7 site-packages oslo_utils excutils.py"""", line 220, in __exit__ self.force_reraise() File """" usr lib python2.7 site-packages oslo_utils excutils.py"""", line 196, in force_reraise six.reraise(self.type_, self.value, self.tb) File """" usr lib python2.7 site-packages nova compute manager.py"""", line 206, in decorated_function return function(self, context, *args, **kwargs) File """" usr lib python2.7 site-packages nova compute manager.py"""", line 2521, in terminate_instance do_terminate_instance(instance, bdms) File """" usr lib python2.7 site-packages oslo_concurrency lockutils.py"""", line 271, in inner return f(*args, **kwargs) File """" usr lib python2.7 site-packages nova compute manager.py"""", line 2519, in do_terminate_instance self._set_instance_obj_error_state(context, instance) File """" usr lib python2.7 site-packages oslo_utils excutils.py"""", line 220, in __exit__ self.force_reraise() File """" usr lib python2.7 site-packages oslo_utils excutils.py"""", line 196, in force_reraise six.reraise(self.type_, self.value, self.tb) File """" usr lib python2.7 site-packages nova compute manager.py"""", line 2509, in do_terminate_instance self._delete_instance(context, instance, bdms) File """" usr lib python2.7 site-packages nova hooks.py"""", line 154, in inner rv = f(*args, **kwargs) File """" usr lib python2.7 site-packages nova compute manager.py"""", line 2482, in _delete_instance system_meta) File """" usr lib python2.7 site-packages nova compute manager.py"""", line 753, in _complete_deletion self._update_resource_tracker(context, instance) File """" usr lib python2.7 site-packages nova compute manager.py"""", line 563, in _update_resource_tracker rt.update_usage(context, instance, instance.node) File """" usr lib python2.7 site-packages oslo_concurrency lockutils.py"""", line 271, in inner return f(*args, **kwargs) File """" usr lib python2.7 site-packages nova compute resource_tracker.py"""", line 285, in update_usage raise Exception Exception None""",1
5827aa63,"""Error updating resources for node localhost.localdomain.: DiskNotFound: Nessun disco in var lib nova instances <*> disk Traceback (most recent call last): File """" usr lib python2.7 site-packages nova compute manager.py"""", line 6752, in update_available_resource_for_node rt.update_available_resource(context, nodename) File """" usr lib python2.7 site-packages nova compute resource_tracker.py"""", line 378, in update_available_resource resources = self.driver.get_available_resource(nodename) File """" usr lib python2.7 site-packages nova virt libvirt driver.py"""", line 5977, in get_available_resource disk_over_committed = self._get_disk_over_committed_size_total() File """" usr lib python2.7 site-packages nova virt libvirt driver.py"""", line 7475, in _get_disk_over_committed_size_total config, block_device_info) File """" usr lib python2.7 site-packages nova virt libvirt driver.py"""", line 7383, in _get_instance_disk_info_from_config dk_size = disk_api.get_allocated_disk_size(path) File """" usr lib python2.7 site-packages nova virt disk api.py"""", line 156, in get_allocated_disk_size return images.qemu_img_info(path).disk_size File """" usr lib python2.7 site-packages nova virt images.py"""", line 57, in qemu_img_info raise exception.DiskNotFound(location=path) DiskNotFound: Nessun disco in var lib nova instances <*> disk None""",2
b5794355,""", instance_uuids) File """" usr lib python2.7 site-packages nova conductor manager.py"""", line 361, in _schedule_instances raise Exception Exception None""",1
66cf9d79,Failed to compute_task_build_instances: : Exception,1
4d3bf8f6,Setting instance to ERROR state.: Exception,1
ea3a8254,""", e, sys.exc_info()) File """" usr lib python2.7 site-packages oslo_utils excutils.py"""", line 220, in __exit__ self.force_reraise() File """" usr lib python2.7 site-packages oslo_utils excutils.py"""", line 196, in force_reraise six.reraise(self.type_, self.value, self.tb) File """" usr lib python2.7 site-packages nova compute manager.py"""", line 206, in decorated_function return function(self, context, *args, **kwargs) File """" usr lib python2.7 site-packages nova compute manager.py"""", line 3149, in reboot_instance self._set_instance_obj_error_state(context, instance) File """" usr lib python2.7 site-packages oslo_utils excutils.py"""", line 220, in __exit__ self.force_reraise() File """" usr lib python2.7 site-packages oslo_utils excutils.py"""", line 196, in force_reraise six.reraise(self.type_, self.value, self.tb) File """" usr lib python2.7 site-packages nova compute manager.py"""", line 3124, in reboot_instance bad_volumes_callback=bad_volumes_callback) File """" usr lib python2.7 site-packages nova virt libvirt driver.py"""", line 1400, in reboot return self._hard_reboot(context, instance, network_info, block_device_info) File """" usr lib python2.7 site-packages nova virt libvirt driver.py"""", line 1429, in _hard_reboot self.destroy(context, instance, network_info, destroy_disks=False, block_device_info=block_device_info) File """" usr lib python2.7 site-packages nova virt libvirt driver.py"""", line 510, in destroy self.cleanup(context, instance, network_info, block_device_info, destroy_disks) File """" usr lib python2.7 site-packages nova virt libvirt driver.py"""", line 584, in cleanup LOG.warning('Ignoring Volume Error on vol %(vol_id)s during delete %(exc)s', <*>'vol_id': vol.get('volume_id'), 'exc': exc}, instance=instance) File """" usr lib python2.7 site-packages oslo_utils excutils.py"""", line 220, in __exit__ self.force_reraise() File """" usr lib python2.7 site-packages oslo_utils excutils.py"""", line 196, in force_reraise six.reraise(self.type_, self.value, self.tb) File """" usr lib python2.7 site-packages nova virt libvirt driver.py"""", line 577, in cleanup self._disconnect_volume(disk_dev, instance) TypeError: _disconnect_volume() takes exactly 4 arguments (3 given) None""",1
aadd25f4,""", encryption=encryption) File """" usr lib python2.7 site-packages nova virt libvirt driver.py"""", line 743, in attach_volume self._check_discard_for_attach_volume(instance) TypeError: _check_discard_for_attach_volume() takes exactly 3 arguments (2 given) None""",1
9728ddcd,"""Error during ComputeManager._sync_power_states: TypeError: object of type 'NoneType' has no len() Traceback (most recent call last): File """" usr lib python2.7 site-packages oslo_service periodic_task.py"""", line 220, in run_periodic_tasks task(self, context) File """" usr lib python2.7 site-packages nova compute manager.py"""", line 6499, in _sync_power_states num_vm_instances = self.driver.get_num_instances() File """" usr lib python2.7 site-packages nova virt driver.py"""", line 181, in get_num_instances return len(self.list_instances()) TypeError: object of type 'NoneType' has no len() None""",1
675f1d72,Attaching volume 12b29c0f-b169-4ea1-a08f-a66f8777a016 to None,1
b216dde5,AttributeError: 'NoneType' object has no attribute 'rpartition' None,2
525d19dd,"""Unexpected exception in API method: TypeError: 'NoneType' object is not iterable Traceback (most recent call last): File """" usr lib python2.7 site-packages nova api openstack extensions.py"""", line 336, in wrapped return f(*args, **kwargs) File """" usr lib python2.7 site-packages nova api validation __init__.py"""", line 181, in wrapper return func(*args, **kwargs) File """" usr lib python2.7 site-packages nova api validation __init__.py"""", line 181, in wrapper return func(*args, **kwargs) File """" usr lib python2.7 site-packages nova api openstack compute servers.py"""", line 168, in detail servers = self._get_servers(req, is_detail=True) File """" usr lib python2.7 site-packages nova api openstack compute servers.py"""", line 322, in _get_servers instance_list.fill_faults() File """" usr lib python2.7 site-packages nova objects instance.py"""", line 1384, in fill_faults for fault in faults: TypeError: 'NoneType' object is not iterable None""",2
aa4549b8,""", e, sys.exc_info()) File """" usr lib python2.7 site-packages oslo_utils excutils.py"""", line 220, in __exit__ self.force_reraise() File """" usr lib python2.7 site-packages oslo_utils excutils.py"""", line 196, in force_reraise six.reraise(self.type_, self.value, self.tb) File """" usr lib python2.7 site-packages nova compute manager.py"""", line 206, in decorated_function return function(self, context, *args, **kwargs) File """" usr lib python2.7 site-packages nova compute manager.py"""", line 3149, in reboot_instance self._set_instance_obj_error_state(context, instance) File """" usr lib python2.7 site-packages oslo_utils excutils.py"""", line 220, in __exit__ self.force_reraise() File """" usr lib python2.7 site-packages oslo_utils excutils.py"""", line 196, in force_reraise six.reraise(self.type_, self.value, self.tb) File """" usr lib python2.7 site-packages nova compute manager.py"""", line 3124, in reboot_instance bad_volumes_callback=bad_volumes_callback) File """" usr lib python2.7 site-packages nova virt libvirt driver.py"""", line 2506, in reboot block_device_info) File """" usr lib python2.7 site-packages nova virt libvirt driver.py"""", line 2575, in _hard_reboot block_device_info=block_device_info) File """" usr lib python2.7 site-packages nova virt libvirt driver.py"""", line 914, in destroy destroy_disks) File """" usr lib python2.7 site-packages nova virt libvirt driver.py"""", line 1025, in cleanup instance=instance) File """" usr lib python2.7 site-packages oslo_utils excutils.py"""", line 220, in __exit__ self.force_reraise() File """" usr lib python2.7 site-packages oslo_utils excutils.py"""", line 196, in force_reraise six.reraise(self.type_, self.value, self.tb) File """" usr lib python2.7 site-packages nova virt libvirt driver.py"""", line 1013, in cleanup self._disconnect_volume(connection_info, disk_dev, instance) File """" usr lib python2.7 site-packages nova virt libvirt driver.py"""", line 1195, in _disconnect_volume vol_driver.disconnect_volume(connection_info, disk_dev, instance) File """" usr lib python2.7 site-packages nova virt libvirt volume iscsi.py"""", line 81, in disconnect_volume super(LibvirtISCSIVolumeDriver, self).disconnect_volume(disk_dev, instance) TypeError: disconnect_volume() takes exactly 4 arguments (3 given) None""",1
cdc8c0bb,"""Error updating resources for node localhost.localdomain.: TypeError: 'NoneType' object is not iterable Traceback (most recent call last): File """" usr lib python2.7 site-packages nova compute manager.py"""", line 6752, in update_available_resource_for_node rt.update_available_resource(context, nodename) File """" usr lib python2.7 site-packages nova compute resource_tracker.py"""", line 688, in update_available_resource resources = self.driver.get_available_resource(nodename) File """" usr lib python2.7 site-packages nova virt libvirt driver.py"""", line 5977, in get_available_resource disk_over_committed = self._get_disk_over_committed_size_total() File """" usr lib python2.7 site-packages nova virt libvirt driver.py"""", line 7460, in _get_disk_over_committed_size_total ctx, instance_uuids) File """" usr lib python2.7 site-packages nova objects block_device.py"""", line 271, in bdms_by_instance_uuid return base.obj_make_dict_of_lists(context, cls, bdms, 'instance_uuid') File """" usr lib python2.7 site-packages nova objects base.py"""", line 292, in obj_make_dict_of_lists for obj in obj_list: TypeError: 'NoneType' object is not iterable None""",3
d82cb15d,"""Exception during message handling: ValueError: Field `ec2_ids' cannot be None Traceback (most recent call last): File """" usr lib python2.7 site-packages oslo_messaging rpc server.py"""", line 160, in _process_incoming res = self.dispatcher.dispatch(message) File """" usr lib python2.7 site-packages oslo_messaging rpc dispatcher.py"""", line 213, in dispatch return self._do_dispatch(endpoint, method, ctxt, args) File """" usr lib python2.7 site-packages oslo_messaging rpc dispatcher.py"""", line 183, in _do_dispatch result = func(ctxt, **new_args) File """" usr lib python2.7 site-packages nova conductor manager.py"""", line 1125, in schedule_and_build_instances instance.create() File """" usr lib python2.7 site-packages oslo_versionedobjects base.py"""", line 226, in wrapper return fn(self, *args, **kwargs) File """" usr lib python2.7 site-packages nova objects instance.py"""", line 561, in create self._load_ec2_ids() File """" usr lib python2.7 site-packages nova objects instance.py"""", line 918, in _load_ec2_ids self.ec2_ids = objects.EC2Ids.get_by_instance(self._context, self) File """" usr lib python2.7 site-packages oslo_versionedobjects base.py"""", line 72, in setter field_value = field.coerce(self, name, value) File """" usr lib python2.7 site-packages oslo_versionedobjects fields.py"""", line 193, in coerce return self._null(obj, attr) File """" usr lib python2.7 site-packages oslo_versionedobjects fields.py"""", line 171, in _null raise ValueError(_(""""Field `%s' cannot be None"""") % attr) ValueError: Field `ec2_ids' cannot be None None""",1
e58cad65,"""Unexpected exception in API method: TypeError: object of type 'NoneType' has no len() Traceback (most recent call last): File """" usr lib python2.7 site-packages nova api openstack extensions.py"""", line 336, in wrapped return f(*args, **kwargs) File """" usr lib python2.7 site-packages nova api validation __init__.py"""", line 181, in wrapper return func(*args, **kwargs) File """" usr lib python2.7 site-packages nova api validation __init__.py"""", line 181, in wrapper return func(*args, **kwargs) File """" usr lib python2.7 site-packages nova api openstack compute servers.py"""", line <*> in <*> servers = self._get_servers(req, <*> File """" usr lib python2.7 site-packages nova api openstack compute servers.py"""", line 311, in _get_servers sort_keys=sort_keys, sort_dirs=sort_dirs) File """" usr lib python2.7 site-packages nova compute api.py"""", line 2457, in get_all limit = (limit - len(cell0_instances)) if limit else limit TypeError: object of type 'NoneType' has no len() None""",9
9a2c8541,"""Error updating resources for node localhost.localdomain.: TypeError: 'NoneType' object is not iterable Traceback (most recent call last): File """" usr lib python2.7 site-packages nova compute manager.py"""", line 6752, in update_available_resource_for_node rt.update_available_resource(context, nodename) File """" usr lib python2.7 site-packages nova compute resource_tracker.py"""", line 688, in update_available_resource resources = self.driver.get_available_resource(nodename) File """" usr lib python2.7 site-packages nova virt libvirt driver.py"""", line 5977, in get_available_resource disk_over_committed = self._get_disk_over_committed_size_total() File """" usr lib python2.7 site-packages nova virt libvirt driver.py"""", line 7456, in _get_disk_over_committed_size_total local_instances = <*>inst.uuid: inst for inst in local_instance_list} TypeError: 'NoneType' object is not iterable None""",5
d95e1207,"""Error during ComputeManager._run_pending_deletes: TypeError: object of type 'NoneType' has no len() Traceback (most recent call last): File """" usr lib python2.7 site-packages oslo_service periodic_task.py"""", line 220, in run_periodic_tasks task(self, context) File """" usr lib python2.7 site-packages nova compute manager.py"""", line 7140, in _run_pending_deletes LOG.debug('There are %d instances to clean', len(instances)) TypeError: object of type 'NoneType' has no len() None""",1
d12829f8,"""Error during ComputeManager._heal_instance_info_cache: TypeError: 'NoneType' object is not iterable Traceback (most recent call last): File """" usr lib python2.7 site-packages oslo_service periodic_task.py"""", line 220, in run_periodic_tasks task(self, context) File """" usr lib python2.7 site-packages nova compute manager.py"""", line 6068, in _heal_instance_info_cache for inst in db_instances: TypeError: 'NoneType' object is not iterable None""",5
2e1a0cd9,"""Error during ComputeManager._sync_power_states: TypeError: object of type 'NoneType' has no len() Traceback (most recent call last): File """" usr lib python2.7 site-packages oslo_service periodic_task.py"""", line 220, in run_periodic_tasks task(self, context) File """" usr lib python2.7 site-packages nova compute manager.py"""", line 6500, in _sync_power_states num_db_instances = len(db_instances) TypeError: object of type 'NoneType' has no len() None""",1
252847ed,)}) TypeError: 'NoneType' object is not iterable None,2
7b3e2eac,""", e, sys.exc_info()) File """" usr lib python2.7 site-packages oslo_utils excutils.py"""", line 220, in __exit__ self.force_reraise() File """" usr lib python2.7 site-packages oslo_utils excutils.py"""", line 196, in force_reraise six.reraise(self.type_, self.value, self.tb) File """" usr lib python2.7 site-packages nova compute manager.py"""", line 206, in decorated_function return function(self, context, *args, **kwargs) File """" usr lib python2.7 site-packages nova compute manager.py"""", line 3149, in reboot_instance self._set_instance_obj_error_state(context, instance) File """" usr lib python2.7 site-packages oslo_utils excutils.py"""", line 220, in __exit__ self.force_reraise() File """" usr lib python2.7 site-packages oslo_utils excutils.py"""", line 196, in force_reraise six.reraise(self.type_, self.value, self.tb) File """" usr lib python2.7 site-packages nova compute manager.py"""", line 3124, in reboot_instance bad_volumes_callback=bad_volumes_callback) File """" usr lib python2.7 site-packages nova virt libvirt driver.py"""", line 2506, in reboot block_device_info) File """" usr lib python2.7 site-packages nova virt libvirt driver.py"""", line 2575, in _hard_reboot block_device_info=block_device_info) File """" usr lib python2.7 site-packages nova virt libvirt driver.py"""", line 914, in destroy destroy_disks) File """" usr lib python2.7 site-packages nova virt libvirt driver.py"""", line 1025, in cleanup instance=instance) File """" usr lib python2.7 site-packages oslo_utils excutils.py"""", line 220, in __exit__ self.force_reraise() File """" usr lib python2.7 site-packages oslo_utils excutils.py"""", line 196, in force_reraise six.reraise(self.type_, self.value, self.tb) File """" usr lib python2.7 site-packages nova virt libvirt driver.py"""", line 1013, in cleanup self._disconnect_volume(connection_info, disk_dev, instance) File """" usr lib python2.7 site-packages nova virt libvirt driver.py"""", line 1195, in _disconnect_volume vol_driver.disconnect_volume(connection_info, disk_dev, instance) File """" usr lib python2.7 site-packages nova virt libvirt volume iscsi.py"""", line 76, in disconnect_volume self.connector.disconnect_volume(None) File """" usr lib python2.7 site-packages os_brick utils.py"""", line 150, in trace_logging_wrapper result = f(*args, **kwargs) File """" usr lib python2.7 site-packages oslo_concurrency lockutils.py"""", line 271, in inner return f(*args, **kwargs) TypeError: disconnect_volume() takes at least 3 arguments (2 given) None""",1
622b6a3f,Ignoring Volume Error on vol None during delete disconnect_volume() takes at least 3 arguments (2 given),1
c9c98d3b,TypeError: 'NoneType' object has no attribute '__getitem__' None,33
8c9b4bef,) None TypeError: 'NoneType' object has no attribute '__getitem__' None None,4
6aab68e3,Port <*> from network info_cache is no longer associated with instance in Neutron. Removing from network info_cache.,2
44aebf8e,"Could not clean up failed build, not rescheduling. Error: 'NoneType' object has no attribute '__getitem__'",2
85222adb,Exception dispatching event <LifecycleEvent: <*> c0ca284b-5a6f-4a18-94b8-ab374cf84123 => <*> 'NoneType' object has no attribute '__getitem__',3
1553c20a,"Exception dispatching event <LifecycleEvent: 1530059118.89, c0ca284b-5a6f-4a18-94b8-ab374cf84123 => In pausa>: 'NoneType' object has no attribute '__getitem__'",1
7fd638a9,get() takes exactly 1 argument (2 given),3
0f2ef0f1,"""Unexpected exception in API method: TypeError: 'NoneType' object is not iterable Traceback (most recent call last): File """" usr lib python2.7 site-packages nova api openstack extensions.py"""", line 336, in wrapped return f(*args, **kwargs) File """" usr lib python2.7 site-packages nova api validation __init__.py"""", line 181, in wrapper return func(*args, **kwargs) File """" usr lib python2.7 site-packages nova api validation __init__.py"""", line 181, in wrapper return func(*args, **kwargs) File """" usr lib python2.7 site-packages nova api openstack compute servers.py"""", line <*> in <*> servers = self._get_servers(req, <*> File """" usr lib python2.7 site-packages nova api openstack compute servers.py"""", line 311, in _get_servers sort_keys=sort_keys, sort_dirs=sort_dirs) File """" usr lib python2.7 site-packages nova compute api.py"""", line 2449, in get_all sort_dirs=sort_dirs) File """" usr lib python2.7 site-packages nova compute api.py"""", line 2596, in _get_instances_by_filters expected_attrs=fields, sort_keys=sort_keys, sort_dirs=sort_dirs) File """" usr lib python2.7 site-packages oslo_versionedobjects base.py"""", line 184, in wrapper result = fn(cls, context, *args, **kwargs) File """" usr lib python2.7 site-packages nova objects instance.py"""", line 1252, in get_by_filters expected_attrs) File """" usr lib python2.7 site-packages nova objects instance.py"""", line 1196, in _make_instance_list for db_inst in db_inst_list: TypeError: 'NoneType' object is not iterable None""",9
7d5b1608,Failed to revert task state for instance. Error: 'NoneType' object is not iterable,2
ef42c00b,"""Error during <*> TypeError: 'NoneType' object is not iterable Traceback (most recent call last): File """" usr lib python2.7 site-packages oslo_service periodic_task.py"""", line 220, in run_periodic_tasks task(self, context) File """" usr lib python2.7 site-packages nova compute manager.py"""", line <*> in <*> use_slave=True) File """" usr lib python2.7 site-packages oslo_versionedobjects base.py"""", line 177, in wrapper args, kwargs) File """" usr lib python2.7 site-packages nova conductor rpcapi.py"""", line 240, in object_class_action_versions args=args, kwargs=kwargs) File """" usr lib python2.7 site-packages oslo_messaging rpc client.py"""", line 122, in call result = self.transport._send(self.target, msg_ctxt, msg, wait_for_reply=True, timeout=timeout, retry=self.retry) File """" usr lib python2.7 site-packages oslo_messaging transport.py"""", line 123, in _send timeout=timeout, retry=retry) File """" usr lib python2.7 site-packages oslo_messaging _drivers amqpdriver.py"""", line 566, in send retry=retry) File """" usr lib python2.7 site-packages oslo_messaging _drivers amqpdriver.py"""", line 557, in _send raise result TypeError: 'NoneType' object is not iterable Traceback (most recent call last): None File """" usr lib python2.7 site-packages nova conductor manager.py"""", line 124, in _object_dispatch return getattr(target, method)(*args, **kwargs) None File """" usr lib python2.7 site-packages oslo_versionedobjects base.py"""", line 184, in wrapper result = fn(cls, context, *args, **kwargs) None File """" usr lib python2.7 site-packages nova objects instance.py"""", line 1267, in get_by_host expected_attrs) None File """" usr lib python2.7 site-packages nova objects instance.py"""", line 1196, in _make_instance_list for db_inst in db_inst_list: None TypeError: 'NoneType' object is not iterable None None""",7
2abe7800,""", use_slave=True) File """" usr lib python2.7 site-packages oslo_versionedobjects base.py"""", line 177, in wrapper args, kwargs) File """" usr lib python2.7 site-packages nova conductor rpcapi.py"""", line 240, in object_class_action_versions args=args, kwargs=kwargs) File """" usr lib python2.7 site-packages oslo_messaging rpc client.py"""", line 122, in call result = self.transport._send(self.target, msg_ctxt, msg, wait_for_reply=True, timeout=timeout, retry=self.retry) File """" usr lib python2.7 site-packages oslo_messaging transport.py"""", line 123, in _send timeout=timeout, retry=retry) File """" usr lib python2.7 site-packages oslo_messaging _drivers amqpdriver.py"""", line 566, in send retry=retry) File """" usr lib python2.7 site-packages oslo_messaging _drivers amqpdriver.py"""", line 557, in _send raise result TypeError: 'NoneType' object is not iterable Traceback (most recent call last): None File """" usr lib python2.7 site-packages nova conductor manager.py"""", line 124, in _object_dispatch return getattr(target, method)(*args, **kwargs) None File """" usr lib python2.7 site-packages oslo_versionedobjects base.py"""", line 184, in wrapper result = fn(cls, context, *args, **kwargs) None File """" usr lib python2.7 site-packages nova objects instance.py"""", line 1267, in get_by_host expected_attrs) None File """" usr lib python2.7 site-packages nova objects instance.py"""", line 1196, in _make_instance_list for db_inst in db_inst_list: None TypeError: 'NoneType' object is not iterable None None""",10
7366954a,"""= ec2utils.id_to_ec2_inst_id(instance.uuid) File """" usr lib python2.7 site-packages nova api ec2 ec2utils.py"""", line 188, in id_to_ec2_inst_id int_id = get_int_id_from_instance_uuid(ctxt, instance_id) File """" usr lib python2.7 site-packages nova api ec2 ec2utils.py"""", line 49, in memoizer value = func(context, reqid) File """" usr lib python2.7 site-packages nova api ec2 ec2utils.py"""", line 301, in get_int_id_from_instance_uuid return imap.id AttributeError: 'NoneType' object has no attribute 'id' None""",2
53a5a044,"""Error updating resources for node localhost.localdomain.: TypeError: 'NoneType' object is not iterable Traceback (most recent call last): File """" usr lib python2.7 site-packages nova compute manager.py"""", line 6756, in update_available_resource_for_node rt.update_available_resource(context, nodename) File """" usr lib python2.7 site-packages nova compute resource_tracker.py"""", line 688, in update_available_resource resources = self.driver.get_available_resource(nodename) File """" usr lib python2.7 site-packages nova virt libvirt driver.py"""", line 5977, in get_available_resource disk_over_committed = self._get_disk_over_committed_size_total() File """" usr lib python2.7 site-packages nova virt libvirt driver.py"""", line 7463, in _get_disk_over_committed_size_total ctx, filters, use_slave=True) File """" usr lib python2.7 site-packages oslo_versionedobjects base.py"""", line 177, in wrapper args, kwargs) File """" usr lib python2.7 site-packages nova conductor rpcapi.py"""", line 240, in object_class_action_versions args=args, kwargs=kwargs) File """" usr lib python2.7 site-packages oslo_messaging rpc client.py"""", line 122, in call result = self.transport._send(self.target, msg_ctxt, msg, wait_for_reply=True, timeout=timeout, retry=self.retry) File """" usr lib python2.7 site-packages oslo_messaging transport.py"""", line 123, in _send timeout=timeout, retry=retry) File """" usr lib python2.7 site-packages oslo_messaging _drivers amqpdriver.py"""", line 566, in send retry=retry) File """" usr lib python2.7 site-packages oslo_messaging _drivers amqpdriver.py"""", line 557, in _send raise result TypeError: 'NoneType' object is not iterable Traceback (most recent call last): None File """" usr lib python2.7 site-packages nova conductor manager.py"""", line 124, in _object_dispatch return getattr(target, method)(*args, **kwargs) None File """" usr lib python2.7 site-packages oslo_versionedobjects base.py"""", line 184, in wrapper result = fn(cls, context, *args, **kwargs) None File """" usr lib python2.7 site-packages nova objects instance.py"""", line 1252, in get_by_filters expected_attrs) None File """" usr lib python2.7 site-packages nova objects instance.py"""", line 1196, in _make_instance_list for db_inst in db_inst_list: None TypeError: 'NoneType' object is not iterable None None""",5
00222bb8,"""Error during ComputeManager._run_pending_deletes: TypeError: 'NoneType' object is not iterable Traceback (most recent call last): File """" usr lib python2.7 site-packages oslo_service periodic_task.py"""", line 220, in run_periodic_tasks task(self, context) File """" usr lib python2.7 site-packages nova compute manager.py"""", line 7143, in _run_pending_deletes context, filters, expected_attrs=attrs, use_slave=True) File """" usr lib python2.7 site-packages oslo_versionedobjects base.py"""", line 177, in wrapper args, kwargs) File """" usr lib python2.7 site-packages nova conductor rpcapi.py"""", line 240, in object_class_action_versions args=args, kwargs=kwargs) File """" usr lib python2.7 site-packages oslo_messaging rpc client.py"""", line 122, in call result = self.transport._send(self.target, msg_ctxt, msg, wait_for_reply=True, timeout=timeout, retry=self.retry) File """" usr lib python2.7 site-packages oslo_messaging transport.py"""", line 123, in _send timeout=timeout, retry=retry) File """" usr lib python2.7 site-packages oslo_messaging _drivers amqpdriver.py"""", line 566, in send retry=retry) File """" usr lib python2.7 site-packages oslo_messaging _drivers amqpdriver.py"""", line 557, in _send raise result TypeError: 'NoneType' object is not iterable Traceback (most recent call last): None File """" usr lib python2.7 site-packages nova conductor manager.py"""", line 124, in _object_dispatch return getattr(target, method)(*args, **kwargs) None File """" usr lib python2.7 site-packages oslo_versionedobjects base.py"""", line 184, in wrapper result = fn(cls, context, *args, **kwargs) None File """" usr lib python2.7 site-packages nova objects instance.py"""", line 1252, in get_by_filters expected_attrs) None File """" usr lib python2.7 site-packages nova objects instance.py"""", line 1196, in _make_instance_list for db_inst in db_inst_list: None TypeError: 'NoneType' object is not iterable None None""",1
8fe5e47c,""")}) File """" usr lib python2.7 site-packages oslo_versionedobjects base.py"""", line 184, in wrapper result = fn(cls, context, *args, **kwargs) File """" usr lib python2.7 site-packages nova objects instance.py"""", line 1252, in get_by_filters expected_attrs) File """" usr lib python2.7 site-packages nova objects instance.py"""", line 1196, in _make_instance_list for db_inst in db_inst_list: TypeError: 'NoneType' object is not iterable None""",3
4cc9541b,""", e, sys.exc_info()) File """" usr lib python2.7 site-packages oslo_utils excutils.py"""", line 220, in __exit__ self.force_reraise() File """" usr lib python2.7 site-packages oslo_utils excutils.py"""", line 196, in force_reraise six.reraise(self.type_, self.value, self.tb) File """" usr lib python2.7 site-packages nova compute manager.py"""", line 239, in decorated_function return function(self, context, *args, **kwargs) File """" usr lib python2.7 site-packages nova compute manager.py"""", line 1521, in terminate_instance do_terminate_instance(instance, bdms) File """" usr lib python2.7 site-packages oslo_concurrency lockutils.py"""", line 271, in inner return f(*args, **kwargs) File """" usr lib python2.7 site-packages nova compute manager.py"""", line 1520, in do_terminate_instance self._set_instance_obj_error_state(context, instance) File """" usr lib python2.7 site-packages oslo_utils excutils.py"""", line 220, in __exit__ self.force_reraise() File """" usr lib python2.7 site-packages oslo_utils excutils.py"""", line 196, in force_reraise six.reraise(self.type_, self.value, self.tb) File """" usr lib python2.7 site-packages nova compute manager.py"""", line 1514, in do_terminate_instance self._delete_instance(context, instance, bdms) File """" usr lib python2.7 site-packages nova hooks.py"""", line 154, in inner rv = f(*args, **kwargs) File """" usr lib python2.7 site-packages nova compute manager.py"""", line 1484, in _delete_instance self._shutdown_instance(context, instance, bdms) File """" usr lib python2.7 site-packages nova compute manager.py"""", line <*> in _shutdown_instance <*> instance, requested_networks) File """" usr lib python2.7 site-packages nova compute manager.py"""", line <*> in _try_deallocate_network self._set_instance_obj_error_state(context, instance) File """" usr lib python2.7 site-packages oslo_utils excutils.py"""", line 220, in __exit__ self.force_reraise() File """" usr lib python2.7 site-packages oslo_utils excutils.py"""", line 196, in force_reraise six.reraise(self.type_, self.value, self.tb) File """" usr lib python2.7 site-packages nova compute manager.py"""", line <*> in _try_deallocate_network <*> instance, requested_networks) File """" usr lib python2.7 site-packages nova compute manager.py"""", line 1081, in _deallocate_network self.network_api.deallocate_for_instance(context, instance, requested_networks=requested_networks) File """" usr lib python2.7 site-packages nova network neutronv2 api.py"""", line 1184, in deallocate_for_instance neutron = get_client(context) File """" usr lib python2.7 site-packages nova network neutronv2 api.py"""", line 149, in get_client if admin or (context.is_admin and not context.auth_token): AttributeError: 'NoneType' object has no attribute 'is_admin' None""",2
f9547a6c,None TypeError: 'NoneType' object has no attribute '__getitem__' None None,1
0a102ea5,Failed to revert task state for instance. Error: Remote error: DetachedInstanceError Instance <Instance at 0x7fe0a761c910> is not bound to a Session; attribute refresh operation cannot proceed,1
1544fa1c,Failed to revert task state for instance. Error: 'NoneType' object has no attribute <*>,4
ec7fa6ce,"""Unexpected exception in API method: AttributeError: 'NoneType' object has no attribute 'filter_by' Traceback (most recent call last): File """" usr lib python2.7 site-packages nova api openstack extensions.py"""", line 336, in wrapped return f(*args, **kwargs) File """" usr lib python2.7 site-packages nova api openstack compute servers.py"""", line 441, in show instance = self._get_server(context, req, id, is_detail=True) File """" usr lib python2.7 site-packages nova api openstack compute servers.py"""", line 346, in _get_server expected_attrs=expected_attrs) File """" usr lib python2.7 site-packages nova api openstack common.py"""", line 478, in get_instance expected_attrs=expected_attrs) File """" usr lib python2.7 site-packages nova compute api.py"""", line 2327, in get expected_attrs) File """" usr lib python2.7 site-packages nova compute api.py"""", line 2287, in _get_instance context, instance_uuid, expected_attrs=expected_attrs) File """" usr lib python2.7 site-packages oslo_versionedobjects base.py"""", line 184, in wrapper result = fn(cls, context, *args, **kwargs) File """" usr lib python2.7 site-packages nova objects instance.py"""", line 467, in get_by_uuid use_slave=use_slave) File """" usr lib python2.7 site-packages nova db sqlalchemy api.py"""", line 237, in wrapper return f(*args, **kwargs) File """" usr lib python2.7 site-packages nova objects instance.py"""", line 459, in _db_instance_get_by_uuid columns_to_join=columns_to_join) File """" usr lib python2.7 site-packages nova db api.py"""", line 744, in instance_get_by_uuid return IMPL.instance_get_by_uuid(context, uuid, columns_to_join) File """" usr lib python2.7 site-packages nova db sqlalchemy api.py"""", line 202, in wrapper return f(*args, **kwargs) File """" usr lib python2.7 site-packages nova db sqlalchemy api.py"""", line 267, in wrapped return f(context, *args, **kwargs) File """" usr lib python2.7 site-packages nova db sqlalchemy api.py"""", line 1209, in instance_get_by_uuid return _instance_get_by_uuid(context, uuid, columns_to_join=columns_to_join) File """" usr lib python2.7 site-packages nova db sqlalchemy api.py"""", line 1212, in _instance_get_by_uuid result = _build_instance_get(context, columns_to_join=columns_to_join).filter_by(uuid=uuid).first() AttributeError: 'NoneType' object has no attribute 'filter_by' None""",6
6b56e0ae,""") File """" usr lib python2.7 site-packages oslo_versionedobjects base.py"""", line 177, in wrapper args, kwargs) File """" usr lib python2.7 site-packages nova conductor rpcapi.py"""", line 240, in object_class_action_versions args=args, kwargs=kwargs) File """" usr lib python2.7 site-packages oslo_messaging rpc client.py"""", line 122, in call result = self.transport._send(self.target, msg_ctxt, msg, wait_for_reply=True, timeout=timeout, retry=self.retry) File """" usr lib python2.7 site-packages oslo_messaging transport.py"""", line 123, in _send timeout=timeout, retry=retry) File """" usr lib python2.7 site-packages oslo_messaging _drivers amqpdriver.py"""", line 566, in send retry=retry) File """" usr lib python2.7 site-packages oslo_messaging _drivers amqpdriver.py"""", line 557, in _send raise result TypeError: 'NoneType' object is not iterable Traceback (most recent call last): None File """" usr lib python2.7 site-packages nova conductor manager.py"""", line 124, in _object_dispatch return getattr(target, method)(*args, **kwargs) None File """" usr lib python2.7 site-packages oslo_versionedobjects base.py"""", line 184, in wrapper result = fn(cls, context, *args, **kwargs) None File """" usr lib python2.7 site-packages nova objects instance.py"""", line 1275, in get_by_host_and_node expected_attrs) None File """" usr lib python2.7 site-packages nova objects instance.py"""", line 1196, in _make_instance_list for db_inst in db_inst_list: None TypeError: 'NoneType' object is not iterable None None""",11
45a29288,"""Error updating resources for node localhost.localdomain.: InvalidDiskInfo: Il file di informazioni sul disco non \xe8 valido: Impossibile eseguire qemu-img su var lib nova instances <*> disk : Unexpected error while running command. Traceback (most recent call last): File """" usr lib python2.7 site-packages nova compute manager.py"""", line 6752, in update_available_resource_for_node rt.update_available_resource(context, nodename) File """" usr lib python2.7 site-packages nova compute resource_tracker.py"""", line 688, in update_available_resource resources = self.driver.get_available_resource(nodename) File """" usr lib python2.7 site-packages nova virt libvirt driver.py"""", line <*> in get_available_resource disk_over_committed = self._get_disk_over_committed_size_total() File """" usr lib python2.7 site-packages nova virt libvirt driver.py"""", line <*> in _get_disk_over_committed_size_total <*> <*> <*> <*> <*> <*> <*> <*> <*> <*> <*> <*> <*> <*> <*> <*> <*> <*> <*> <*> <*> <*> <*> <*> <*> <*> <*> <*> <*> <*> <*> <*> <*> <*> <*> <*> <*> File """" usr lib python2.7 site-packages nova virt images.py"""", line 82, in qemu_img_info raise exception.InvalidDiskInfo(reason=msg) InvalidDiskInfo: Il file di informazioni sul disco non \xe8 valido: Impossibile eseguire qemu-img su var lib nova instances <*> disk : Unexpected error while running command. Command: usr bin python2 -m oslo_concurrency.prlimit --as=1073741824 --cpu=30 -- env LC_ALL=C LANG=C qemu-img info var lib nova instances <*> disk --force-share Exit code: 1 Stdout: u'' Stderr: u""""qemu-img: Could not open ' var lib nova instances <*> disk': Could not open ' var lib nova instances <*> disk': No such file or directory\n"""" None""",2
50fcf2f8,"""= ec2utils.id_to_ec2_inst_id(instance.uuid) File """" usr lib python2.7 site-packages nova api ec2 ec2utils.py"""", line 188, in id_to_ec2_inst_id int_id = get_int_id_from_instance_uuid(ctxt, instance_id) File """" usr lib python2.7 site-packages nova api ec2 ec2utils.py"""", line 49, in memoizer value = func(context, reqid) File """" usr lib python2.7 site-packages nova api ec2 ec2utils.py"""", line 300, in get_int_id_from_instance_uuid imap = objects.EC2InstanceMapping.get_by_uuid(context, instance_uuid) File """" usr lib python2.7 site-packages oslo_versionedobjects base.py"""", line 184, in wrapper result = fn(cls, context, *args, **kwargs) File """" usr lib python2.7 site-packages nova objects ec2.py"""", line 50, in get_by_uuid db_imap = db.ec2_instance_get_by_uuid(context, instance_uuid) File """" usr lib python2.7 site-packages nova db api.py"""", line 1988, in ec2_instance_get_by_uuid return IMPL.ec2_instance_get_by_uuid(context, instance_uuid) File """" usr lib python2.7 site-packages nova db sqlalchemy api.py"""", line 202, in wrapper return f(*args, **kwargs) File """" usr lib python2.7 site-packages nova db sqlalchemy api.py"""", line 257, in wrapped return f(context, *args, **kwargs) File """" usr lib python2.7 site-packages nova db sqlalchemy api.py"""", line 3628, in ec2_instance_get_by_uuid result = _ec2_instance_get_query(context).filter_by(uuid=instance_uuid).first() AttributeError: 'NoneType' object has no attribute 'filter_by' None""",1
1123e884,""") File """" usr lib python2.7 site-packages oslo_versionedobjects base.py"""", line 177, in wrapper args, kwargs) File """" usr lib python2.7 site-packages nova conductor rpcapi.py"""", line 240, in object_class_action_versions args=args, kwargs=kwargs) File """" usr lib python2.7 site-packages oslo_messaging rpc client.py"""", line 122, in call result = self.transport._send(self.target, msg_ctxt, msg, wait_for_reply=True, timeout=timeout, retry=self.retry) File """" usr lib python2.7 site-packages oslo_messaging transport.py"""", line 123, in _send timeout=timeout, retry=retry) File """" usr lib python2.7 site-packages oslo_messaging _drivers amqpdriver.py"""", line 566, in send retry=retry) File """" usr lib python2.7 site-packages oslo_messaging _drivers amqpdriver.py"""", line 557, in _send raise result TypeError: 'NoneType' object is not iterable Traceback (most recent call last): None File """" usr lib python2.7 site-packages nova conductor manager.py"""", line 124, in _object_dispatch return getattr(target, method)(*args, **kwargs) None File """" usr lib python2.7 site-packages oslo_versionedobjects base.py"""", line 184, in wrapper result = fn(cls, context, *args, **kwargs) None File """" usr lib python2.7 site-packages nova objects instance.py"""", line 1273, in get_by_host_and_node columns_to_join=_expected_cols(expected_attrs)) None File """" usr lib python2.7 site-packages nova db api.py"""", line 809, in instance_get_all_by_host_and_node context, host, node, columns_to_join=columns_to_join) None File """" usr lib python2.7 site-packages nova db sqlalchemy api.py"""", line 257, in wrapped return f(context, *args, **kwargs) None File """" usr lib python2.7 site-packages nova db sqlalchemy api.py"""", line 1552, in instance_get_all_by_host_and_node return _instances_fill_metadata(context, _instance_get_all_query(context, joins=columns_to_join).filter_by(host=host).filter_by(node=node).all(), manual_joins=manual_joins) None File """" usr lib python2.7 site-packages nova db sqlalchemy api.py"""", line 1256, in _instances_fill_metadata for row in _instance_system_metadata_get_multi(context, uuids): None TypeError: 'NoneType' object is not iterable None None""",3
91f835b0,""") None File """" usr lib python2.7 site-packages nova db sqlalchemy api.py"""", line 202, in wrapper return f(*args, **kwargs) None File """" usr lib python2.7 site-packages nova db sqlalchemy api.py"""", line 267, in wrapped return f(context, *args, **kwargs) None File """" usr lib python2.7 site-packages nova db sqlalchemy api.py"""", line 1392, in instance_get_all_by_filters_sort return _instances_fill_metadata(context, query_prefix.all(), manual_joins) None File """" usr lib python2.7 site-packages nova db sqlalchemy api.py"""", line 1256, in _instances_fill_metadata for row in _instance_system_metadata_get_multi(context, uuids): None TypeError: 'NoneType' object is not iterable None None""",1
2d5a76a1,Creating iscsi_target for volume: <*>,414
2c4cd650,Initialize volume connection completed successfully.,828
187f16b1,Update volume admin metadata completed successfully.,414
ac898734,Attaching volume <*> to instance <*> at mountpoint dev vdb on host None.,414
a9082531,Attach volume completed successfully.,828
765e83aa,Detaching volume <*> from instance <*>,412
5cfa4fb9,Removing iscsi_target: <*>,412
34288474,GET 10.0.20.46:8776 <*> <*> volumes <*>,641
bd1518d3,Function 'cinder.service.Service.report_state' run outlasted interval by <*> sec,3
07088ca0,GET 10.0.20.21:8776 <*> <*> volumes <*>,492
59e838c8,Dominio non trovato: no domain with matching uuid <*> <*> libvirtError: Dominio non trovato: no domain with matching uuid <*> <*>,6
42e1f454,GET 10.0.20.22:8776 <*> <*> volumes <*>,536
4f29c1c4,"Instance <*> is not being actively managed by this compute host but has allocations referencing this compute host: <*>u'resources': <*>u'VCPU': 1, u'MEMORY_MB': 512, u'DISK_GB': 1}}. Skipping heal of allocation because we do not know what to do.",3
e1cac0ad,GET 10.0.20.23:8776 <*> <*> volumes <*>,418
69b73df0,GET 10.0.20.25:8776 <*> <*> volumes <*>,787
53282674,"""Error updating resources for node localhost.localdomain.: InvalidDiskInfo: Il file di informazioni sul disco non \xe8 valido: Impossibile eseguire qemu-img su var lib nova instances <*> disk : Unexpected error while running command. Traceback (most recent call last): File """" usr lib python2.7 site-packages nova compute manager.py"""", line 6752, in update_available_resource_for_node rt.update_available_resource(context, nodename) File """" usr lib python2.7 site-packages nova compute resource_tracker.py"""", line 688, in update_available_resource resources = self.driver.get_available_resource(nodename) File """" usr lib python2.7 site-packages nova virt libvirt driver.py"""", line 5977, in get_available_resource disk_over_committed = self._get_disk_over_committed_size_total() File """" usr lib python2.7 site-packages nova virt libvirt driver.py"""", line 7475, in _get_disk_over_committed_size_total config, block_device_info) File """" usr lib python2.7 site-packages nova virt libvirt driver.py"""", line 7394, in _get_instance_disk_info_from_config virt_size = disk_api.get_disk_size(path) File """" usr lib python2.7 site-packages nova virt disk api.py"""", line 146, in get_disk_size return images.qemu_img_info(path).virtual_size File """" usr lib python2.7 site-packages nova virt images.py"""", line 82, in qemu_img_info raise exception.InvalidDiskInfo(reason=msg) InvalidDiskInfo: Il file di informazioni sul disco non \xe8 valido: Impossibile eseguire qemu-img su var lib nova instances <*> disk : Unexpected error while running command. Command: usr bin python2 -m oslo_concurrency.prlimit --as=1073741824 --cpu=30 -- env LC_ALL=C LANG=C qemu-img info var lib nova instances <*> disk --force-share Exit code: 1 Stdout: u'' Stderr: u""""qemu-img: Could not open ' var lib nova instances <*> disk': Could not open ' var lib nova instances <*> disk': No such file or directory\n"""" None""",2
e54a6a63,Timeout waiting for vif plugging callback for instance with vm_state building and task_state spawning.: Timeout: 300 seconds,4
2d378e90,GET 10.0.20.28:8776 <*> <*> volumes <*>,849
15bd1003,", u'container_format': u'bare', u'created_at': datetime.datetime(2018, <*> <*> <*> <*> <*> <*> <*> <*> <*> <*> <*> <*> <*> <*> tzinfo=<iso8601.Utc>), u'visibility': u'public', 'properties': <*>}, u'owner': <*> u'protected': False, u'id': <*> u'file': u' v2 images <*> file', u'checksum': u'443b7623e27ecf03dc9e01ee93f67afe', u'min_disk': 0, u'virtual_size': None, u'min_ram': 0, u'size': 12716032}}",8
beafccbd,GET 10.0.20.26:8776 <*> <*> volumes <*>,574
f1219245,GET 10.0.20.27:8776 <*> <*> volumes <*>,481
d2c17fd7,"""Error updating resources for node localhost.localdomain.: DiskNotFound: Nessun disco in var lib nova instances <*> disk Traceback (most recent call last): File """" usr lib python2.7 site-packages nova compute manager.py"""", line 6752, in update_available_resource_for_node rt.update_available_resource(context, nodename) File """" usr lib python2.7 site-packages nova compute resource_tracker.py"""", line 688, in update_available_resource resources = self.driver.get_available_resource(nodename) File """" usr lib python2.7 site-packages nova virt libvirt driver.py"""", line <*> in get_available_resource disk_over_committed = self._get_disk_over_committed_size_total() File """" usr lib python2.7 site-packages nova virt libvirt driver.py"""", line <*> in _get_disk_over_committed_size_total <*> <*> <*> <*> <*> <*> <*> <*> <*> <*> <*> <*> <*> <*> <*> <*> <*> <*> <*> <*> <*> <*> <*> <*> <*> <*> <*> <*> <*> <*> <*> <*> <*> <*> <*> <*> <*> File """" usr lib python2.7 site-packages nova virt images.py"""", line 57, in qemu_img_info raise exception.DiskNotFound(location=path) DiskNotFound: Nessun disco in var lib nova instances <*> disk None""",3
895eb283,Purging deleted rows older than age=1 days from <*>,32
7341b626,Deleted <*> rows from <*>,4
c7af4a07,<*> is not bound.,3
0c60ec03,", u'container_format': u'bare', u'created_at': datetime.datetime(2018, <*> <*> <*> <*> tzinfo=<iso8601.Utc>), u'disk_format': u'qcow2', u'updated_at': datetime.datetime(2018, <*> <*> <*> <*> tzinfo=<iso8601.Utc>), u'visibility': u'public', 'properties': <*>}, u'owner': <*> u'protected': False, u'id': <*> u'file': u' v2 images <*> file', u'checksum': u'443b7623e27ecf03dc9e01ee93f67afe', u'min_disk': 0, u'virtual_size': None, u'min_ram': 0, u'size': 12716032}}",5
260be159,"ERROR (ClientException): Errore API non previsto. Segnalarlo a bugs.launchpad.net nova e allegare il log Nova API, se possibile.",2
6ec5a18d,"API ERROR: nova list --all-tenant ; ERROR (ClientException): Errore API non previsto. Segnalarlo a bugs.launchpad.net nova e allegare il log Nova API, se possibile. <*> <*> (HTTP 500) (Request-ID: <*>",2
de919eb5,"Volume lo stato deve essere availableoppureerroroppureerror_restoringoppureerror_extendingoppureerror_managing e must not be migrating, attached, belong to a group, have snapshots or be disassociated from snapshots after volume transfer.",2
8dc8b04c,Attempt 2 to bind port 5a24e113-0df8-46ca-88f5-930dcbef5e28,1
0fd492f7,: 2018-06-30T01:35:16Z|00001|jsonrpc|WARN|tcp:127.0.0.1:6640: receive error: Connection reset by peer,1
4355a1db,dies due to the error: 2018-06-30T01:35:16Z|00001|jsonrpc|WARN|tcp:127.0.0.1:6640: receive error: Connection reset by peer,1
a2926c3f,tcp:127.0.0.1:6640: send error: Broken pipe,1
94f0ba06,tcp:127.0.0.1:6640: connection dropped (Broken pipe),1
d793c869,unknown dpid 112585511767880,1
57fe8e47,"ofctl request version=None,msg_type=None,msg_len=None,xid=None,OFPFlowStatsRequest(cookie=0,cookie_mask=0,flags=0,match=OFPMatch(oxm_fields=<*>}),out_group=4294967295,out_port=4294967295,table_id=23,type=1) error Datapath Invalid 112585511767880: InvalidDatapath: Datapath Invalid 112585511767880",1
acd26318,"""Failed to communicate with the switch: RuntimeError: ofctl request version=None,msg_type=None,msg_len=None,xid=None,OFPFlowStatsRequest(cookie=0,cookie_mask=0,flags=0,match=OFPMatch(oxm_fields=<*>}),out_group=4294967295,out_port=4294967295,table_id=23,type=1) error Datapath Invalid 112585511767880 Traceback (most recent call last): File """" usr lib python2.7 site-packages neutron plugins ml2 drivers openvswitch agent openflow native br_int.py"""", line 52, in check_canary_table flows = self.dump_flows(constants.CANARY_TABLE) File """" usr lib python2.7 site-packages neutron plugins ml2 drivers openvswitch agent openflow native ofswitch.py"""", line 147, in dump_flows reply_multi=True) File """" usr lib python2.7 site-packages neutron plugins ml2 drivers openvswitch agent openflow native ofswitch.py"""", line 85, in _send_msg raise RuntimeError(m) RuntimeError: ofctl request version=None,msg_type=None,msg_len=None,xid=None,OFPFlowStatsRequest(cookie=0,cookie_mask=0,flags=0,match=OFPMatch(oxm_fields=<*>}),out_group=4294967295,out_port=4294967295,table_id=23,type=1) error Datapath Invalid 112585511767880 None""",1
a47b8c12,OVS is dead. OVSNeutronAgent will keep running and checking OVS status periodically.,1
a72188c8,Interface monitor is not active,13
0f7a78c1,Function 'cinder.service.Service.periodic_tasks' run outlasted interval by 6.94 sec,1
6d53c0af,volume service is down. (host: localhost.localdomain@lvm),1
041f292c,"""File """" usr lib python2.7 site-packages nova api openstack compute views servers.py"""", line 134, in show """"status"""": self._get_vm_status(instance), File """" usr lib python2.7 site-packages nova api openstack compute views servers.py"""", line 239, in _get_vm_status instance.get(""""task_state"""")) File """" usr lib python2.7 site-packages oslo_versionedobjects base.py"""", line 774, in get return getattr(self, key) File """" usr lib python2.7 site-packages oslo_versionedobjects base.py"""", line 67, in getter self.obj_load_attr(name) File """" usr lib python2.7 site-packages nova objects instance.py"""", line 1040, in obj_load_attr reason=_('attribute %s not lazy-loadable') % attrname) ObjectActionError: Azione dell'oggetto obj_load_attr non riuscita perch\xe9: attribute task_state not lazy-loadable None""",5
3cb0ad99,<class 'nova.exception.ObjectActionError'> (HTTP 500) (Request-ID: req-0ff7326a-dd13-41ac-89de-510f2020580b),1
